Workbook

Sheet Previsão de Cargas
A1: Central de Comando de Motores | B1: CCM
A2: Valor Nominal da Tensão de Linha | B2: 380 | C2: V
A3: DADOS DE ENTRADA | O3: DADOS DE ENTRADA
A4: Circuito | B4: Origem | C4: Destino | D4: PN - Potência Nominal [HP] | E4: F.P. | F4: Kp (Ip/In) | G4: η - Rendimento [%] | H4: FS - Fator de Serviço | I4: P Potência Ativa [kW] | J4: S Potência Aparente [kVA] | K4: Q Potência Reativa [kVAr] | L4: Corrente | O4: Circuito | P4: Origem | Q4: Destino | R4: Potência Ativa TOTAL (P) [kW] | S4: Potência Reativa TOTAL (Q) [kVAr] | T4: Potência Aparente TOTAL (S) [kVA] | U4: Corrente
L5: IN [A] | M5: IP [A] | U5: IN [A]
A6: 50 - TUE M1 | B6: CCM1 | C6: Colagem e Montagem | D6: 5 | E6: 0.77 | F6: 8.3 | G6: 89.5 | H6: 1.25 | I6: =D6*0.745/(G6/100) -> 4.1620112 | J6: =I6/E6 -> 5.4052093 | K6: =SQRT(J6^2-I6^2) -> 3.4487608 | L6: =J6*1000/(SQRT(3)*$B$2) -> 8.2123659 | M6: =F6*L6 -> 68.162637 | O6: Alimentador QD1 | P6: QGBT | Q6: QD1 | R6: 55.961 | S6: 40.536424 | T6: =SQRT(R6^2+S6^2) -> 69.100182 | U6: 120.96539
A7: 51 - TUE M2 | D7: 5 | E7: 0.77 | F7: 8.3 | G7: 89.5 | H7: 1.25 | I7: =D7*0.745/(G7/100) -> 4.1620112 | J7: =I7/E7 -> 5.4052093 | K7: =SQRT(J7^2-I7^2) -> 3.4487608 | L7: =J7*1000/(SQRT(3)*$B$2) -> 8.2123659 | M7: =F7*L7 -> 68.162637 | O7: Alimentador QD2 | Q7: QD2 | R7: 77.6251 | S7: 54.400025 | T7: =SQRT(R7^2+S7^2) -> 94.789339 | U7: 161.92454
A8: 52 - TUE M3 | D8: 5 | E8: 0.77 | F8: 8.3 | G8: 89.5 | H8: 1.25 | I8: =D8*0.745/(G8/100) -> 4.1620112 | J8: =I8/E8 -> 5.4052093 | K8: =SQRT(J8^2-I8^2) -> 3.4487608 | L8: =J8*1000/(SQRT(3)*$B$2) -> 8.2123659 | M8: =F8*L8 -> 68.162637 | O8: Alimentador QD3 | Q8: QD3 | R8: 19.5458 | S8: 9.082416 | T8: =SQRT(R8^2+S8^2) -> 21.552925 | U8: 42.545059
A9: 53 - TUE M4 | D9: 5 | E9: 0.77 | F9: 8.3 | G9: 89.5 | H9: 1.25 | I9: =D9*0.745/(G9/100) -> 4.1620112 | J9: =I9/E9 -> 5.4052093 | K9: =SQRT(J9^2-I9^2) -> 3.4487608 | L9: =J9*1000/(SQRT(3)*$B$2) -> 8.2123659 | M9: =F9*L9 -> 68.162637 | O9: Alimentador QD4 | Q9: QD4 | R9: 22.596 | S9: 9.4807533 | T9: =SQRT(R9^2+S9^2) -> 24.504365 | U9: 53.023454
A10: 54 - TUE M5 | D10: 15 | E10: 0.83 | F10: 8.3 | G10: 92.4 | H10: 1.25 | I10: =D10*0.745/(G10/100) -> 12.094156 | J10: =I10/E10 -> 14.571272 | K10: =SQRT(J10^2-I10^2) -> 8.1273221 | L10: =J10*1000/(SQRT(3)*$B$2) -> 22.138758 | M10: =F10*L10 -> 183.75169 | O10: Alimentador CCM1 | Q10: CCM1 | R10: =SUM(I6:I13) -> 65.024668 | S10: =SUM(K6:K13) -> 46.304332 | T10: =SQRT(R10^2+S10^2) -> 79.826678 | U10: =T10*1000/(SQRT(3)*$B$2) -> 121.28409
A11: 55 - TUE M6 | D11: 15 | E11: 0.83 | F11: 8.3 | G11: 92.4 | H11: 1.25 | I11: =D11*0.745/(G11/100) -> 12.094156 | J11: =I11/E11 -> 14.571272 | K11: =SQRT(J11^2-I11^2) -> 8.1273221 | L11: =J11*1000/(SQRT(3)*$B$2) -> 22.138758 | M11: =F11*L11 -> 183.75169 | O11: Alimentador CCM2 | Q11: CCM2 | R11: =SUM(I14:I19) -> 79.944496 | S11: =SUM(K14:K19) -> 55.350632 | T11: =SQRT(R11^2+S11^2) -> 97.235872 | U11: =T11*1000/(SQRT(3)*$B$2) -> 147.73462
A12: 56 - TUE M7 | D12: 15 | E12: 0.83 | F12: 8.3 | G12: 92.4 | H12: 1.25 | I12: =D12*0.745/(G12/100) -> 12.094156 | J12: =I12/E12 -> 14.571272 | K12: =SQRT(J12^2-I12^2) -> 8.1273221 | L12: =J12*1000/(SQRT(3)*$B$2) -> 22.138758 | M12: =F12*L12 -> 183.75169 | O12: Alimentador CCM3 | Q12: CCM3 | R12: =SUM(I20:I27) -> 119.73904 | S12: =SUM(K20:K27) -> 83.684688 | T12: =SQRT(R12^2+S12^2) -> 146.0841 | U12: =T12*1000/(SQRT(3)*$B$2) -> 221.95183
A13: 57 - TUE M8 | D13: 15 | E13: 0.83 | F13: 8.3 | G13: 92.4 | H13: 1.25 | I13: =D13*0.745/(G13/100) -> 12.094156 | J13: =I13/E13 -> 14.571272 | K13: =SQRT(J13^2-I13^2) -> 8.1273221 | L13: =J13*1000/(SQRT(3)*$B$2) -> 22.138758 | M13: =F13*L13 -> 183.75169 | O13: Alimentador CCM4 | Q13: CCM4 | R13: =SUM(I28:I29) -> 117.13836 | S13: =SUM(K28:K29) -> 66.385371 | T13: =SQRT(R13^2+S13^2) -> 134.6418 | U13: =T13*1000/(SQRT(3)*$B$2) -> 204.56705
A14: 58 - TUE M9 | B14: CCM2 | C14: Tornear e chanfrar | D14: 10 | E14: 0.84 | F14: 8.2 | G14: 92 | H14: 1.25 | I14: =D14*0.745/(G14/100) -> 8.0978261 | J14: =I14/E14 -> 9.6402692 | K14: =SQRT(J14^2-I14^2) -> 5.2306789 | L14: =J14*1000/(SQRT(3)*$B$2) -> 14.646874 | M14: =F14*L14 -> 120.10436
A15: 59 - TUE M10 | D15: 10 | E15: 0.84 | F15: 8.2 | G15: 92 | H15: 1.25 | I15: =D15*0.745/(G15/100) -> 8.0978261 | J15: =I15/E15 -> 9.6402692 | K15: =SQRT(J15^2-I15^2) -> 5.2306789 | L15: =J15*1000/(SQRT(3)*$B$2) -> 14.646874 | M15: =F15*L15 -> 120.10436
A16: 60 - TUE M11 | D16: 10 | E16: 0.84 | F16: 8.2 | G16: 92 | H16: 1.25 | I16: =D16*0.745/(G16/100) -> 8.0978261 | J16: =I16/E16 -> 9.6402692 | K16: =SQRT(J16^2-I16^2) -> 5.2306789 | L16: =J16*1000/(SQRT(3)*$B$2) -> 14.646874 | M16: =F16*L16 -> 120.10436
A17: 61 - TUE M12 | D17: 10 | E17: 0.84 | F17: 8.2 | G17: 92 | H17: 1.25 | I17: =D17*0.745/(G17/100) -> 8.0978261 | J17: =I17/E17 -> 9.6402692 | K17: =SQRT(J17^2-I17^2) -> 5.2306789 | L17: =J17*1000/(SQRT(3)*$B$2) -> 14.646874 | M17: =F17*L17 -> 120.10436
A18: 62 - TUE M13 | D18: 30 | E18: 0.81 | F18: 8 | G18: 94 | H18: 1.25 | I18: =D18*0.745/(G18/100) -> 23.776596 | J18: =I18/E18 -> 29.353822 | K18: =SQRT(J18^2-I18^2) -> 17.213958 | L18: =J18*1000/(SQRT(3)*$B$2) -> 44.598518 | M18: =F18*L18 -> 356.78815
A19: 63 - TUE M14 | D19: 30 | E19: 0.81 | F19: 8 | G19: 94 | H19: 1.25 | I19: =D19*0.745/(G19/100) -> 23.776596 | J19: =I19/E19 -> 29.353822 | K19: =SQRT(J19^2-I19^2) -> 17.213958 | L19: =J19*1000/(SQRT(3)*$B$2) -> 44.598518 | M19: =F19*L19 -> 356.78815
A20: 64 - TUE M15 | B20: CCM3 | C20: Polimento | D20: 7.5 | E20: 0.78 | F20: 7.3 | G20: 91 | H20: 1.25 | I20: =D20*0.745/(G20/100) -> 6.1401099 | J20: =I20/E20 -> 7.8719358 | K20: =SQRT(J20^2-I20^2) -> 4.9260961 | L20: =J20*1000/(SQRT(3)*$B$2) -> 11.960169 | M20: =F20*L20 -> 87.309234
A21: 65 - TUE M16 | D21: 7.5 | E21: 0.78 | F21: 7.3 | G21: 91 | H21: 1.25 | I21: =D21*0.745/(G21/100) -> 6.1401099 | J21: =I21/E21 -> 7.8719358 | K21: =SQRT(J21^2-I21^2) -> 4.9260961 | L21: =J21*1000/(SQRT(3)*$B$2) -> 11.960169 | M21: =F21*L21 -> 87.309234
A22: 66 - TUE M17 | D22: 7.5 | E22: 0.78 | F22: 7.3 | G22: 91 | H22: 1.25 | I22: =D22*0.745/(G22/100) -> 6.1401099 | J22: =I22/E22 -> 7.8719358 | K22: =SQRT(J22^2-I22^2) -> 4.9260961 | L22: =J22*1000/(SQRT(3)*$B$2) -> 11.960169 | M22: =F22*L22 -> 87.309234
A23: 67 - TUE M18 | D23: 7.5 | E23: 0.78 | F23: 7.3 | G23: 91 | H23: 1.25 | I23: =D23*0.745/(G23/100) -> 6.1401099 | J23: =I23/E23 -> 7.8719358 | K23: =SQRT(J23^2-I23^2) -> 4.9260961 | L23: =J23*1000/(SQRT(3)*$B$2) -> 11.960169 | M23: =F23*L23 -> 87.309234
A24: 68 - TUE M19 | D24: 20 | E24: 0.81 | F24: 9 | G24: 93 | H24: 1.25 | I24: =D24*0.745/(G24/100) -> 16.021505 | J24: =I24/E24 -> 19.779636 | K24: =SQRT(J24^2-I24^2) -> 11.59937 | L24: =J24*1000/(SQRT(3)*$B$2) -> 30.052048 | M24: =F24*L24 -> 270.46843
A25: 69 - TUE M20 | D25: 20 | E25: 0.81 | F25: 9 | G25: 93 | H25: 1.25 | I25: =D25*0.745/(G25/100) -> 16.021505 | J25: =I25/E25 -> 19.779636 | K25: =SQRT(J25^2-I25^2) -> 11.59937 | L25: =J25*1000/(SQRT(3)*$B$2) -> 30.052048 | M25: =F25*L25 -> 270.46843
A26: 70 - TUE M21 | D26: 40 | E26: 0.84 | F26: 7 | G26: 94.4 | H26: 1.25 | I26: =D26*0.745/(G26/100) -> 31.567797 | J26: =I26/E26 -> 37.58071 | K26: =SQRT(J26^2-I26^2) -> 20.390782 | L26: =J26*1000/(SQRT(3)*$B$2) -> 57.097982 | M26: =F26*L26 -> 399.68587
A27: 71 - TUE M22 | D27: 40 | E27: 0.84 | F27: 7 | G27: 94.4 | H27: 1.25 | I27: =D27*0.745/(G27/100) -> 31.567797 | J27: =I27/E27 -> 37.58071 | K27: =SQRT(J27^2-I27^2) -> 20.390782 | L27: =J27*1000/(SQRT(3)*$B$2) -> 57.097982 | M27: =F27*L27 -> 399.68587
A28: 72 - TUE M23 | B28: CCM4 | C28: Sistemas de serras | D28: 75 | E28: 0.87 | F28: 7.5 | G28: 95.4 | H28: 1.25 | I28: =D28*0.745/(G28/100) -> 58.569182 | J28: =I28/E28 -> 67.320899 | K28: =SQRT(J28^2-I28^2) -> 33.192685 | L28: =J28*1000/(SQRT(3)*$B$2) -> 102.28352 | M28: =F28*L28 -> 767.12643
A29: 73 - TUE M24 | D29: 75 | E29: 0.87 | F29: 7.5 | G29: 95.4 | H29: 1.25 | I29: =D29*0.745/(G29/100) -> 58.569182 | J29: =I29/E29 -> 67.320899 | K29: =SQRT(J29^2-I29^2) -> 33.192685 | L29: =J29*1000/(SQRT(3)*$B$2) -> 102.28352 | M29: =F29*L29 -> 767.12643

Sheet Capac.Cond.Corre.
A2: CRITÉRIO DA CAPACIDADE DE CONDUÇÃO DE CORRENTE
A3: Circuito N° - Tipo | B3: Origem | C3: Destino | D3: IN [A] | E3: FT (F.Temp.) | F3: N° Circ. Agrup. | G3: FA (F.Agrup.) | H3: IN' [A] | I3: Método Instala. | J3: Tipo de Isolação | K3: N° Cond. Carregados | L3: S2 - Seção (mm²)
A4: ='Previsão de Cargas'!A6 -> 50 - TUE M1 | B4: ='Previsão de Cargas'!B6 -> CCM1 | C4: Motor M1 | D4: ='Previsão de Cargas'!L6 -> 8.2123659 | E4: 1 | F4: 12 | G4: 0.72 | H4: =D4/(E4*G4) -> 11.406064 | I4: E | J4: PVC 0,6/1 kV (Sintenax) | K4: 3 | L4: 1.5
A5: ='Previsão de Cargas'!A7 -> 51 - TUE M2 | C5: Motor M2 | D5: ='Previsão de Cargas'!L7 -> 8.2123659 | E5: 1 | F5: 12 | G5: 0.72 | H5: =D5/(E5*G5) -> 11.406064 | I5: E | J5: PVC 0,6/1 kV (Sintenax) | K5: 3 | L5: 1.5
A6: ='Previsão de Cargas'!A8 -> 52 - TUE M3 | C6: Motor M3 | D6: ='Previsão de Cargas'!L8 -> 8.2123659 | E6: 1 | F6: 12 | G6: 0.72 | H6: =D6/(E6*G6) -> 11.406064 | I6: E | J6: PVC 0,6/1 kV (Sintenax) | K6: 3 | L6: 1.5
A7: ='Previsão de Cargas'!A9 -> 53 - TUE M4 | C7: Motor M4 | D7: ='Previsão de Cargas'!L9 -> 8.2123659 | E7: 1 | F7: 12 | G7: 0.72 | H7: =D7/(E7*G7) -> 11.406064 | I7: E | J7: PVC 0,6/1 kV (Sintenax) | K7: 3 | L7: 1.5
A8: ='Previsão de Cargas'!A10 -> 54 - TUE M5 | C8: Motor M5 | D8: ='Previsão de Cargas'!L10 -> 22.138758 | E8: 1 | F8: 12 | G8: 0.72 | H8: =D8/(E8*G8) -> 30.748274 | I8: E | J8: PVC 0,6/1 kV (Sintenax) | K8: 3 | L8: 4
A9: ='Previsão de Cargas'!A11 -> 55 - TUE M6 | C9: Motor M6 | D9: ='Previsão de Cargas'!L11 -> 22.138758 | E9: 1 | F9: 12 | G9: 0.72 | H9: =D9/(E9*G9) -> 30.748274 | I9: E | J9: PVC 0,6/1 kV (Sintenax) | K9: 3 | L9: 4
A10: ='Previsão de Cargas'!A12 -> 56 - TUE M7 | C10: Motor M7 | D10: ='Previsão de Cargas'!L12 -> 22.138758 | E10: 1 | F10: 12 | G10: 0.72 | H10: =D10/(E10*G10) -> 30.748274 | I10: E | J10: PVC 0,6/1 kV (Sintenax) | K10: 3 | L10: 4
A11: ='Previsão de Cargas'!A13 -> 57 - TUE M8 | C11: Motor M8 | D11: ='Previsão de Cargas'!L13 -> 22.138758 | E11: 1 | F11: 12 | G11: 0.72 | H11: =D11/(E11*G11) -> 30.748274 | I11: E | J11: PVC 0,6/1 kV (Sintenax) | K11: 3 | L11: 4
A12: ='Previsão de Cargas'!A14 -> 58 - TUE M9 | B12: ='Previsão de Cargas'!B14 -> CCM2 | C12: Motor M9 | D12: ='Previsão de Cargas'!L14 -> 14.646874 | E12: 1 | F12: 8 | G12: 0.72 | H12: =D12/(E12*G12) -> 20.34288 | I12: E | J12: PVC 0,6/1 kV (Sintenax) | K12: 3 | L12: 2.5
A13: ='Previsão de Cargas'!A15 -> 59 - TUE M10 | C13: Motor M10 | D13: ='Previsão de Cargas'!L15 -> 14.646874 | E13: 1 | F13: 8 | G13: 0.72 | H13: =D13/(E13*G13) -> 20.34288 | I13: E | J13: PVC 0,6/1 kV (Sintenax) | K13: 3 | L13: 2.5
A14: ='Previsão de Cargas'!A16 -> 60 - TUE M11 | C14: Motor M11 | D14: ='Previsão de Cargas'!L16 -> 14.646874 | E14: 1 | F14: 8 | G14: 0.72 | H14: =D14/(E14*G14) -> 20.34288 | I14: E | J14: PVC 0,6/1 kV (Sintenax) | K14: 3 | L14: 2.5
A15: ='Previsão de Cargas'!A17 -> 61 - TUE M12 | C15: Motor M12 | D15: ='Previsão de Cargas'!L17 -> 14.646874 | E15: 1 | F15: 8 | G15: 0.72 | H15: =D15/(E15*G15) -> 20.34288 | I15: E | J15: PVC 0,6/1 kV (Sintenax) | K15: 3 | L15: 2.5
A16: ='Previsão de Cargas'!A18 -> 62 - TUE M13 | C16: Motor M13 | D16: ='Previsão de Cargas'!L18 -> 44.598518 | E16: 1 | F16: 8 | G16: 0.72 | H16: =D16/(E16*G16) -> 61.942387 | I16: E | J16: PVC 0,6/1 kV (Sintenax) | K16: 3 | L16: 16
A17: ='Previsão de Cargas'!A19 -> 63 - TUE M14 | C17: Motor M14 | D17: ='Previsão de Cargas'!L19 -> 44.598518 | E17: 1 | F17: 8 | G17: 0.72 | H17: =D17/(E17*G17) -> 61.942387 | I17: E | J17: PVC 0,6/1 kV (Sintenax) | K17: 3 | L17: 16
A18: ='Previsão de Cargas'!A20 -> 64 - TUE M15 | B18: ='Previsão de Cargas'!B20 -> CCM3 | C18: Motor M15 | D18: ='Previsão de Cargas'!L20 -> 11.960169 | E18: 1 | F18: 12 | G18: 0.72 | H18: =D18/(E18*G18) -> 16.611346 | I18: E | J18: PVC 0,6/1 kV (Sintenax) | K18: 3 | L18: 1.5
A19: ='Previsão de Cargas'!A21 -> 65 - TUE M16 | C19: Motor M16 | D19: ='Previsão de Cargas'!L21 -> 11.960169 | E19: 1 | F19: 12 | G19: 0.72 | H19: =D19/(E19*G19) -> 16.611346 | I19: E | J19: PVC 0,6/1 kV (Sintenax) | K19: 3 | L19: 1.5
A20: ='Previsão de Cargas'!A22 -> 66 - TUE M17 | C20: Motor M17 | D20: ='Previsão de Cargas'!L22 -> 11.960169 | E20: 1 | F20: 12 | G20: 0.72 | H20: =D20/(E20*G20) -> 16.611346 | I20: E | J20: PVC 0,6/1 kV (Sintenax) | K20: 3 | L20: 1.5
A21: ='Previsão de Cargas'!A23 -> 67 - TUE M18 | C21: Motor M18 | D21: ='Previsão de Cargas'!L23 -> 11.960169 | E21: 1 | F21: 12 | G21: 0.72 | H21: =D21/(E21*G21) -> 16.611346 | I21: E | J21: PVC 0,6/1 kV (Sintenax) | K21: 3 | L21: 1.5
A22: ='Previsão de Cargas'!A24 -> 68 - TUE M19 | C22: Motor M19 | D22: ='Previsão de Cargas'!L24 -> 30.052048 | E22: 1 | F22: 12 | G22: 0.72 | H22: =D22/(E22*G22) -> 41.738956 | I22: E | J22: PVC 0,6/1 kV (Sintenax) | K22: 3 | L22: 6
A23: ='Previsão de Cargas'!A25 -> 69 - TUE M20 | C23: Motor M20 | D23: ='Previsão de Cargas'!L25 -> 30.052048 | E23: 1 | F23: 12 | G23: 0.72 | H23: =D23/(E23*G23) -> 41.738956 | I23: E | J23: PVC 0,6/1 kV (Sintenax) | K23: 3 | L23: 6
A24: ='Previsão de Cargas'!A26 -> 70 - TUE M21 | C24: Motor M21 | D24: ='Previsão de Cargas'!L26 -> 57.097982 | E24: 1 | F24: 12 | G24: 0.72 | H24: =D24/(E24*G24) -> 79.302753 | I24: E | J24: PVC 0,6/1 kV (Sintenax) | K24: 3 | L24: 16
A25: ='Previsão de Cargas'!A27 -> 71 - TUE M22 | C25: Motor M22 | D25: ='Previsão de Cargas'!L27 -> 57.097982 | E25: 1 | F25: 12 | G25: 0.72 | H25: =D25/(E25*G25) -> 79.302753 | I25: E | J25: PVC 0,6/1 kV (Sintenax) | K25: 3 | L25: 16
A26: ='Previsão de Cargas'!A28 -> 72 - TUE M23 | B26: ='Previsão de Cargas'!B28 -> CCM4 | C26: Motor M23 | D26: ='Previsão de Cargas'!L28 -> 102.28352 | E26: 1 | F26: 2 | G26: 0.88 | H26: =D26/(E26*G26) -> 116.23128 | I26: F | J26: EPR 0,6/1 kV (Afumex) | K26: 3 | L26: 25
A27: ='Previsão de Cargas'!A29 -> 73 - TUE M24 | C27: Motor M24 | D27: ='Previsão de Cargas'!L29 -> 102.28352 | E27: 1 | F27: 2 | G27: 0.88 | H27: =D27/(E27*G27) -> 116.23128 | I27: F | J27: EPR 0,6/1 kV (Afumex) | K27: 3 | L27: 25
A28: ='Previsão de Cargas'!O6 -> Alimentador QD1 | B28: QGBT | C28: ='Previsão de Cargas'!Q6 -> QD1 | D28: ='Previsão de Cargas'!U6 -> 120.96539 | E28: 1 | F28: 6 | G28: 0.79 | H28: =D28/(E28*G28) -> 153.12075 | I28: F | J28: EPR 0,6/1 kV (Afumex) | K28: 3 | L28: 35
A29: ='Previsão de Cargas'!O7 -> Alimentador QD2 | C29: ='Previsão de Cargas'!Q7 -> QD2 | D29: ='Previsão de Cargas'!U7 -> 161.92454 | E29: 1 | F29: 6 | G29: 0.79 | H29: =D29/(E29*G29) -> 204.96778 | I29: F | J29: EPR 0,6/1 kV (Afumex) | K29: 3 | L29: 50
A30: ='Previsão de Cargas'!O8 -> Alimentador QD3 | C30: ='Previsão de Cargas'!Q8 -> QD3 | D30: ='Previsão de Cargas'!U8 -> 42.545059 | E30: 1 | F30: 1 | G30: 1 | H30: =D30/(E30*G30) -> 42.545059 | I30: B1 | J30: PVC 450/750 V (T1, eletroduto embutido) | K30: 3 | L30: 10
A31: ='Previsão de Cargas'!O9 -> Alimentador QD4 | C31: ='Previsão de Cargas'!Q9 -> QD4 | D31: ='Previsão de Cargas'!U9 -> 53.023454 | E31: 1 | F31: 1 | G31: 1 | H31: =D31/(E31*G31) -> 53.023454 | I31: B1 | J31: PVC 450/750 V (T1, eletroduto embutido) | K31: 3 | L31: 16
A32: ='Previsão de Cargas'!O10 -> Alimentador CCM1 | C32: ='Previsão de Cargas'!Q10 -> CCM1 | D32: =Demanda!E34 -> 80.532636 | E32: 1 | F32: 6 | G32: 0.79 | H32: =D32/(E32*G32) -> 101.94005 | I32: F | J32: EPR 0,6/1 kV (Afumex) | K32: 3 | L32: 16
A33: ='Previsão de Cargas'!O11 -> Alimentador CCM2 | C33: ='Previsão de Cargas'!Q11 -> CCM2 | D33: =Demanda!E35 -> 99.522631 | E33: 1 | F33: 6 | G33: 0.79 | H33: =D33/(E33*G33) -> 125.97801 | I33: F | J33: EPR 0,6/1 kV (Afumex) | K33: 3 | L33: 25
A34: ='Previsão de Cargas'!O12 -> Alimentador CCM3 | C34: ='Previsão de Cargas'!Q12 -> CCM3 | D34: =Demanda!E36 -> 150.16348 | E34: 1 | F34: 6 | G34: 0.79 | H34: =D34/(E34*G34) -> 190.08035 | I34: F | J34: EPR 0,6/1 kV (Afumex) | K34: 3 | L34: 50
A35: ='Previsão de Cargas'!O13 -> Alimentador CCM4 | C35: ='Previsão de Cargas'!Q13 -> CCM4 | D35: =Demanda!E37 -> 160.176 | E35: 1 | F35: 6 | G35: 0.79 | H35: =D35/(E35*G35) -> 202.75443 | I35: F | J35: EPR 0,6/1 kV (Afumex) | K35: 3 | L35: 50

Sheet Queda de Tensão
A2: CRITÉRIO DE QUEDA DE TENSÃO
A3: Circuito N° - Tipo | B3: Origem | C3: Destino | D3: IN [A] | E3: VN [V] | F3: k | G3: ρ [Ω.mm²/m] | H3: L [m] | I3: Queda de tensão (Máx) [%] | J3: S3 - Seção Calculada [mm²] | K3: SF - Seção Comercial [mm²]
A4: ='Capac.Cond.Corre.'!A4 -> 50 - TUE M1 | B4: ='Previsão de Cargas'!B6 -> CCM1 | C4: Motor M1 | D4: ='Capac.Cond.Corre.'!D4 -> 8.2123659 | E4: =_Vnom -> 380 | F4: =SQRT(3) -> 1.7320508 | G4: 0.0178 | H4: 19 | I4: 2.5 | J4: =F4*G4*H4*D4/((I4/100)*E4) -> 0.50638277 | K4: 2.5
A5: ='Capac.Cond.Corre.'!A5 -> 51 - TUE M2 | C5: Motor M2 | D5: ='Capac.Cond.Corre.'!D5 -> 8.2123659 | E5: =_Vnom -> 380 | F5: =SQRT(3) -> 1.7320508 | G5: 0.0178 | H5: 17.2 | I5: 2.5 | J5: =F5*G5*H5*D5/((I5/100)*E5) -> 0.45840966 | K5: 2.5
A6: ='Capac.Cond.Corre.'!A6 -> 52 - TUE M3 | C6: Motor M3 | D6: ='Capac.Cond.Corre.'!D6 -> 8.2123659 | E6: =_Vnom -> 380 | F6: =SQRT(3) -> 1.7320508 | G6: 0.0178 | H6: 17.6 | I6: 2.5 | J6: =F6*G6*H6*D6/((I6/100)*E6) -> 0.46907035 | K6: 2.5
A7: ='Capac.Cond.Corre.'!A7 -> 53 - TUE M4 | C7: Motor M4 | D7: ='Capac.Cond.Corre.'!D7 -> 8.2123659 | E7: =_Vnom -> 380 | F7: =SQRT(3) -> 1.7320508 | G7: 0.0178 | H7: 19.3 | I7: 2.5 | J7: =F7*G7*H7*D7/((I7/100)*E7) -> 0.51437828 | K7: 2.5
A8: ='Capac.Cond.Corre.'!A8 -> 54 - TUE M5 | C8: Motor M5 | D8: ='Capac.Cond.Corre.'!D8 -> 22.138758 | E8: =_Vnom -> 380 | F8: =SQRT(3) -> 1.7320508 | G8: 0.0178 | H8: 23.5 | I8: 2.5 | J8: =F8*G8*H8*D8/((I8/100)*E8) -> 1.6884108 | K8: 4
A9: ='Capac.Cond.Corre.'!A9 -> 55 - TUE M6 | C9: Motor M6 | D9: ='Capac.Cond.Corre.'!D9 -> 22.138758 | E9: =_Vnom -> 380 | F9: =SQRT(3) -> 1.7320508 | G9: 0.0178 | H9: 21.7 | I9: 2.5 | J9: =F9*G9*H9*D9/((I9/100)*E9) -> 1.5590858 | K9: 4
A10: ='Capac.Cond.Corre.'!A10 -> 56 - TUE M7 | C10: Motor M7 | D10: ='Capac.Cond.Corre.'!D10 -> 22.138758 | E10: =_Vnom -> 380 | F10: =SQRT(3) -> 1.7320508 | G10: 0.0178 | H10: 19.9 | I10: 2.5 | J10: =F10*G10*H10*D10/((I10/100)*E10) -> 1.4297607 | K10: 4
A11: ='Capac.Cond.Corre.'!A11 -> 57 - TUE M8 | C11: Motor M8 | D11: ='Capac.Cond.Corre.'!D11 -> 22.138758 | E11: =_Vnom -> 380 | F11: =SQRT(3) -> 1.7320508 | G11: 0.0178 | H11: 18.1 | I11: 2.5 | J11: =F11*G11*H11*D11/((I11/100)*E11) -> 1.3004356 | K11: 4
A12: ='Capac.Cond.Corre.'!A12 -> 58 - TUE M9 | B12: ='Previsão de Cargas'!B14 -> CCM2 | C12: Motor M9 | D12: ='Capac.Cond.Corre.'!D12 -> 14.646874 | E12: =_Vnom -> 380 | F12: =SQRT(3) -> 1.7320508 | G12: 0.0178 | H12: 14 | I12: 2.5 | J12: =F12*G12*H12*D12/((I12/100)*E12) -> 0.66547232 | K12: 4
A13: ='Capac.Cond.Corre.'!A13 -> 59 - TUE M10 | C13: Motor M10 | D13: ='Capac.Cond.Corre.'!D13 -> 14.646874 | E13: =_Vnom -> 380 | F13: =SQRT(3) -> 1.7320508 | G13: 0.0178 | H13: 16 | I13: 2.5 | J13: =F13*G13*H13*D13/((I13/100)*E13) -> 0.76053979 | K13: 4
A14: ='Capac.Cond.Corre.'!A14 -> 60 - TUE M11 | C14: Motor M11 | D14: ='Capac.Cond.Corre.'!D14 -> 14.646874 | E14: =_Vnom -> 380 | F14: =SQRT(3) -> 1.7320508 | G14: 0.0178 | H14: 16.2 | I14: 2.5 | J14: =F14*G14*H14*D14/((I14/100)*E14) -> 0.77004654 | K14: 4
A15: ='Capac.Cond.Corre.'!A15 -> 61 - TUE M12 | C15: Motor M12 | D15: ='Capac.Cond.Corre.'!D15 -> 14.646874 | E15: =_Vnom -> 380 | F15: =SQRT(3) -> 1.7320508 | G15: 0.0178 | H15: 18.2 | I15: 2.5 | J15: =F15*G15*H15*D15/((I15/100)*E15) -> 0.86511402 | K15: 4
A16: ='Capac.Cond.Corre.'!A16 -> 62 - TUE M13 | C16: Motor M13 | D16: ='Capac.Cond.Corre.'!D16 -> 44.598518 | E16: =_Vnom -> 380 | F16: =SQRT(3) -> 1.7320508 | G16: 0.0178 | H16: 17.4 | I16: 2.5 | J16: =F16*G16*H16*D16/((I16/100)*E16) -> 2.5184116 | K16: 16
A17: ='Capac.Cond.Corre.'!A17 -> 63 - TUE M14 | C17: Motor M14 | D17: ='Capac.Cond.Corre.'!D17 -> 44.598518 | E17: =_Vnom -> 380 | F17: =SQRT(3) -> 1.7320508 | G17: 0.0178 | H17: 15.6 | I17: 2.5 | J17: =F17*G17*H17*D17/((I17/100)*E17) -> 2.2578862 | K17: 16
A18: ='Capac.Cond.Corre.'!A18 -> 64 - TUE M15 | B18: ='Previsão de Cargas'!B20 -> CCM3 | C18: Motor M15 | D18: ='Capac.Cond.Corre.'!D18 -> 11.960169 | E18: =_Vnom -> 380 | F18: =SQRT(3) -> 1.7320508 | G18: 0.0178 | H18: 19.8 | I18: 2.5 | J18: =F18*G18*H18*D18/((I18/100)*E18) -> 0.76852771 | K18: 2.5
A19: ='Capac.Cond.Corre.'!A19 -> 65 - TUE M16 | C19: Motor M16 | D19: ='Capac.Cond.Corre.'!D19 -> 11.960169 | E19: =_Vnom -> 380 | F19: =SQRT(3) -> 1.7320508 | G19: 0.0178 | H19: 18.3 | I19: 2.5 | J19: =F19*G19*H19*D19/((I19/100)*E19) -> 0.71030592 | K19: 2.5
A20: ='Capac.Cond.Corre.'!A20 -> 66 - TUE M17 | C20: Motor M17 | D20: ='Capac.Cond.Corre.'!D20 -> 11.960169 | E20: =_Vnom -> 380 | F20: =SQRT(3) -> 1.7320508 | G20: 0.0178 | H20: 16.6 | I20: 2.5 | J20: =F20*G20*H20*D20/((I20/100)*E20) -> 0.64432121 | K20: 2.5
A21: ='Capac.Cond.Corre.'!A21 -> 67 - TUE M18 | C21: Motor M18 | D21: ='Capac.Cond.Corre.'!D21 -> 11.960169 | E21: =_Vnom -> 380 | F21: =SQRT(3) -> 1.7320508 | G21: 0.0178 | H21: 15.2 | I21: 2.5 | J21: =F21*G21*H21*D21/((I21/100)*E21) -> 0.58998087 | K21: 2.5
A22: ='Capac.Cond.Corre.'!A22 -> 68 - TUE M19 | C22: Motor M19 | D22: ='Capac.Cond.Corre.'!D22 -> 30.052048 | E22: =_Vnom -> 380 | F22: =SQRT(3) -> 1.7320508 | G22: 0.0178 | H22: 21.3 | I22: 2.5 | J22: =F22*G22*H22*D22/((I22/100)*E22) -> 2.0773549 | K22: 6
A23: ='Capac.Cond.Corre.'!A23 -> 69 - TUE M20 | C23: Motor M20 | D23: ='Capac.Cond.Corre.'!D23 -> 30.052048 | E23: =_Vnom -> 380 | F23: =SQRT(3) -> 1.7320508 | G23: 0.0178 | H23: 18.2 | I23: 2.5 | J23: =F23*G23*H23*D23/((I23/100)*E23) -> 1.7750169 | K23: 6
A24: ='Capac.Cond.Corre.'!A24 -> 70 - TUE M21 | C24: Motor M21 | D24: ='Capac.Cond.Corre.'!D24 -> 57.097982 | E24: =_Vnom -> 380 | F24: =SQRT(3) -> 1.7320508 | G24: 0.0178 | H24: 22.8 | I24: 2.5 | J24: =F24*G24*H24*D24/((I24/100)*E24) -> 4.224863 | K24: 16
A25: ='Capac.Cond.Corre.'!A25 -> 71 - TUE M22 | C25: Motor M22 | D25: ='Capac.Cond.Corre.'!D25 -> 57.097982 | E25: =_Vnom -> 380 | F25: =SQRT(3) -> 1.7320508 | G25: 0.0178 | H25: 19.7 | I25: 2.5 | J25: =F25*G25*H25*D25/((I25/100)*E25) -> 3.6504299 | K25: 16
A26: ='Capac.Cond.Corre.'!A26 -> 72 - TUE M23 | B26: ='Previsão de Cargas'!B28 -> CCM4 | C26: Motor M23 | D26: ='Capac.Cond.Corre.'!D26 -> 102.28352 | E26: =_Vnom -> 380 | F26: =SQRT(3) -> 1.7320508 | G26: 0.0178 | H26: 20.8 | I26: 2.5 | J26: =F26*G26*H26*D26/((I26/100)*E26) -> 6.9044016 | K26: 35
A27: ='Capac.Cond.Corre.'!A27 -> 73 - TUE M24 | C27: Motor M24 | D27: ='Capac.Cond.Corre.'!D27 -> 102.28352 | E27: =_Vnom -> 380 | F27: =SQRT(3) -> 1.7320508 | G27: 0.0178 | H27: 17 | I27: 2.5 | J27: =F27*G27*H27*D27/((I27/100)*E27) -> 5.6430205 | K27: 35
A28: ='Capac.Cond.Corre.'!A28 -> Alimentador QD1 | B28: QGBT | C28: ='Previsão de Cargas'!Q6 -> QD1 | D28: ='Capac.Cond.Corre.'!D28 -> 120.96539 | E28: =_Vnom -> 380 | F28: =SQRT(3) -> 1.7320508 | G28: 0.0178 | H28: 61.3 | I28: 2.5 | J28: =F28*G28*H28*D28/((I28/100)*E28) -> 24.064599 | K28: 35
A29: ='Capac.Cond.Corre.'!A29 -> Alimentador QD2 | C29: ='Previsão de Cargas'!Q7 -> QD2 | D29: ='Capac.Cond.Corre.'!D29 -> 161.92454 | E29: =_Vnom -> 380 | F29: =SQRT(3) -> 1.7320508 | G29: 0.0178 | H29: 36.3 | I29: 2.5 | J29: =F29*G29*H29*D29/((I29/100)*E29) -> 19.075518 | K29: 70
A30: ='Capac.Cond.Corre.'!A30 -> Alimentador QD3 | C30: ='Previsão de Cargas'!Q8 -> QD3 | D30: ='Capac.Cond.Corre.'!D30 -> 42.545059 | E30: =_Vnom -> 380 | F30: =SQRT(3) -> 1.7320508 | G30: 0.0178 | H30: 25.1 | I30: 2.5 | J30: =F30*G30*H30*D30/((I30/100)*E30) -> 3.4656115 | K30: 10
A31: ='Capac.Cond.Corre.'!A31 -> Alimentador QD4 | C31: ='Previsão de Cargas'!Q9 -> QD4 | D31: ='Capac.Cond.Corre.'!D31 -> 53.023454 | E31: =_Vnom -> 380 | F31: =SQRT(3) -> 1.7320508 | G31: 0.0178 | H31: 15.9 | I31: 2.5 | J31: =F31*G31*H31*D31/((I31/100)*E31) -> 2.7360382 | K31: 16
A32: ='Capac.Cond.Corre.'!A32 -> Alimentador CCM1 | C32: ='Previsão de Cargas'!Q10 -> CCM1 | D32: ='Capac.Cond.Corre.'!D32 -> 80.532636 | E32: =_Vnom -> 380 | F32: =SQRT(3) -> 1.7320508 | G32: 0.0178 | H32: 44.2 | I32: 2.5 | J32: =F32*G32*H32*D32/((I32/100)*E32) -> 11.551841 | K32: 25
A33: ='Capac.Cond.Corre.'!A33 -> Alimentador CCM2 | C33: ='Previsão de Cargas'!Q11 -> CCM2 | D33: ='Capac.Cond.Corre.'!D33 -> 99.522631 | E33: =_Vnom -> 380 | F33: =SQRT(3) -> 1.7320508 | G33: 0.0178 | H33: 64.9 | I33: 2.5 | J33: =F33*G33*H33*D33/((I33/100)*E33) -> 20.961558 | K33: 25
A34: ='Capac.Cond.Corre.'!A34 -> Alimentador CCM3 | C34: ='Previsão de Cargas'!Q12 -> CCM3 | D34: ='Capac.Cond.Corre.'!D34 -> 150.16348 | E34: =_Vnom -> 380 | F34: =SQRT(3) -> 1.7320508 | G34: 0.0178 | H34: 41.4 | I34: 2.5 | J34: =F34*G34*H34*D34/((I34/100)*E34) -> 20.175378 | K34: 50
A35: ='Capac.Cond.Corre.'!A35 -> Alimentador CCM4 | C35: ='Previsão de Cargas'!Q13 -> CCM4 | D35: ='Capac.Cond.Corre.'!D35 -> 160.176 | E35: =_Vnom -> 380 | F35: =SQRT(3) -> 1.7320508 | G35: 0.0178 | H35: 25.2 | I35: 2.5 | J35: =F35*G35*H35*D35/((I35/100)*E35) -> 13.099509 | K35: 70

Sheet Proteção
A3: PROTEÇÕES DOS CENTROS DE COMANDO DOS MOTORES (CCM)
A4: Equipamento | B4: Origem | C4: Destino | D4: ='Capac.Cond.Corre.'!D3 -> IN [A] | E4: ='Previsão de Cargas'!D4:D5 -> PN - Potência Nominal [HP] | F4: Método de Partida | G4: Corrente de partida (IP) [A] | H4: Tempo de partida (TP) [s] | I4: Relé de Sobrecarga | M4: Contator | P4: Fusível Ramal | T4: Tempo de atuação do fusível durante a partida é adequado? (TF> TP) | U4: Fusível compatível com o relé de sobrecarga e contator? (IF ≤ IF,max) | V4: Fusível Geral (FG) | AA4: Chave Geral | AC4: Disjuntor Geral
I5: Corrente Ajuste (IAJ) [A] | J5: Modelo | K5: Faixa de Ajuste [A] | L5: Fusível Máximo (IF,max) [A] | M5: Ie [A] | N5: Modelo | O5: Fusível Máximo (IF,max) [A] | P5: Fusível Mínimo (IF,min) [A] | Q5: Tipo | R5: Fusível Comercial (IF) [A] | S5: Tempo de atuação (TF) [s] | V5: Valor Comercial do Maior Fusível do CCM [A] | W5: Somatório das correntes dos outros motores do CCM [A] | X5: Fusível Geral Mínimo (IFG,min) [A] | Y5: Tipo | Z5: Fusível Comercial (IFG) [A] | AA5: Modelo | AB5: ICG [A] | AC5: Modelo | AD5: IDG [A]
A6: ='Previsão de Cargas'!A6 -> 50 - TUE M1 | B6: ='Previsão de Cargas'!B6 -> CCM1 | C6: Motor M1 | D6: ='Previsão de Cargas'!L6 -> 8.2123659 | E6: ='Previsão de Cargas'!D6 -> 5 | F6: Direta | G6: ='Previsão de Cargas'!M6 -> 68.162637 | H6: 5 | I6: ='Previsão de Cargas'!H6*D6 -> 10.265457 | J6: 3RU11 16-1KB0 | K6: 9 – 12 | L6: 20 | M6: 12 | N6: 3RT10 17-1AQ01 | O6: 20 | P6: =1.2*I6 -> 12.318549 | Q6: Diazed DII gG (5SB2 71) | R6: 20 | S6: 9.2 | T6: =IF(S6>H6,"Sim","Não") -> Sim | U6: =IF(R6<=MIN(L6,O6),"Sim","Não") -> Sim | V6: =MAX(R6:R13) -> 35 | W6: =SUM(D6:D13)-INDEX(D6:D13,MATCH(V6,R6:R13,0)) -> 99.265736 | X6: =V6+W6 -> 134.26574 | Y6: NH00 gG (3NA3 836) | Z6: 160 | AA6: Seccionadora tripolar sob carga 160 A, com base NH00 | AB6: =Z6 -> 160 | AC6: Disjuntor termomagnético tripolar (caixa moldada), no QGBT | AD6: 100
A7: ='Previsão de Cargas'!A7 -> 51 - TUE M2 | C7: Motor M2 | D7: ='Previsão de Cargas'!L7 -> 8.2123659 | E7: ='Previsão de Cargas'!D7 -> 5 | F7: Direta | G7: ='Previsão de Cargas'!M7 -> 68.162637 | H7: 5 | I7: ='Previsão de Cargas'!H7*D7 -> 10.265457 | J7: 3RU11 16-1KB0 | K7: 9 – 12 | L7: 20 | M7: 12 | N7: 3RT10 17-1AQ01 | O7: 20 | P7: =1.2*I7 -> 12.318549 | Q7: Diazed DII gG (5SB2 71) | R7: 20 | S7: 9.2 | T7: =IF(S7>H7,"Sim","Não") -> Sim | U7: =IF(R7<=MIN(L7,O7),"Sim","Não") -> Sim
A8: ='Previsão de Cargas'!A8 -> 52 - TUE M3 | C8: Motor M3 | D8: ='Previsão de Cargas'!L8 -> 8.2123659 | E8: ='Previsão de Cargas'!D8 -> 5 | F8: Direta | G8: ='Previsão de Cargas'!M8 -> 68.162637 | H8: 5 | I8: ='Previsão de Cargas'!H8*D8 -> 10.265457 | J8: 3RU11 16-1KB0 | K8: 9 – 12 | L8: 20 | M8: 12 | N8: 3RT10 17-1AQ01 | O8: 20 | P8: =1.2*I8 -> 12.318549 | Q8: Diazed DII gG (5SB2 71) | R8: 20 | S8: 9.2 | T8: =IF(S8>H8,"Sim","Não") -> Sim | U8: =IF(R8<=MIN(L8,O8),"Sim","Não") -> Sim
A9: ='Previsão de Cargas'!A9 -> 53 - TUE M4 | C9: Motor M4 | D9: ='Previsão de Cargas'!L9 -> 8.2123659 | E9: ='Previsão de Cargas'!D9 -> 5 | F9: Direta | G9: ='Previsão de Cargas'!M9 -> 68.162637 | H9: 5 | I9: ='Previsão de Cargas'!H9*D9 -> 10.265457 | J9: 3RU11 16-1KB0 | K9: 9 – 12 | L9: 20 | M9: 12 | N9: 3RT10 17-1AQ01 | O9: 20 | P9: =1.2*I9 -> 12.318549 | Q9: Diazed DII gG (5SB2 71) | R9: 20 | S9: 9.2 | T9: =IF(S9>H9,"Sim","Não") -> Sim | U9: =IF(R9<=MIN(L9,O9),"Sim","Não") -> Sim
A10: ='Previsão de Cargas'!A10 -> 54 - TUE M5 | C10: Motor M5 | D10: ='Previsão de Cargas'!L10 -> 22.138758 | E10: ='Previsão de Cargas'!D10 -> 15 | F10: Estrela-Triângulo | G10: ='Previsão de Cargas'!M10/3 -> 61.250563 | H10: 5 | I10: ='Previsão de Cargas'!H10*D10/SQRT(3) -> 15.977272 | J10: 3RU11 26-4AB0 | K10: 11 – 16 | L10: 35 | M10: 25 | N10: K1/K2: 3RT10 26-1AQ00 | K3: 3RT10 23-1AQ00 (9 A) | O10: 35 | P10: =1.2*I10*SQRT(3) -> 33.208136 | Q10: Diazed DIII gG (5SB4 11) | R10: 35 | S10: 860 | T10: =IF(S10>H10,"Sim","Não") -> Sim | U10: =IF(R10<=MIN(L10,O10),"Sim","Não") -> Sim
A11: ='Previsão de Cargas'!A11 -> 55 - TUE M6 | C11: Motor M6 | D11: ='Previsão de Cargas'!L11 -> 22.138758 | E11: ='Previsão de Cargas'!D11 -> 15 | F11: Estrela-Triângulo | G11: ='Previsão de Cargas'!M11/3 -> 61.250563 | H11: 5 | I11: ='Previsão de Cargas'!H11*D11/SQRT(3) -> 15.977272 | J11: 3RU11 26-4AB0 | K11: 11 – 16 | L11: 35 | M11: 25 | N11: K1/K2: 3RT10 26-1AQ00 | K3: 3RT10 23-1AQ00 (9 A) | O11: 35 | P11: =1.2*I11*SQRT(3) -> 33.208136 | Q11: Diazed DIII gG (5SB4 11) | R11: 35 | S11: 860 | T11: =IF(S11>H11,"Sim","Não") -> Sim | U11: =IF(R11<=MIN(L11,O11),"Sim","Não") -> Sim
A12: ='Previsão de Cargas'!A12 -> 56 - TUE M7 | C12: Motor M7 | D12: ='Previsão de Cargas'!L12 -> 22.138758 | E12: ='Previsão de Cargas'!D12 -> 15 | F12: Estrela-Triângulo | G12: ='Previsão de Cargas'!M12/3 -> 61.250563 | H12: 5 | I12: ='Previsão de Cargas'!H12*D12/SQRT(3) -> 15.977272 | J12: 3RU11 26-4AB0 | K12: 11 – 16 | L12: 35 | M12: 25 | N12: K1/K2: 3RT10 26-1AQ00 | K3: 3RT10 23-1AQ00 (9 A) | O12: 35 | P12: =1.2*I12*SQRT(3) -> 33.208136 | Q12: Diazed DIII gG (5SB4 11) | R12: 35 | S12: 860 | T12: =IF(S12>H12,"Sim","Não") -> Sim | U12: =IF(R12<=MIN(L12,O12),"Sim","Não") -> Sim
A13: ='Previsão de Cargas'!A13 -> 57 - TUE M8 | C13: Motor M8 | D13: ='Previsão de Cargas'!L13 -> 22.138758 | E13: ='Previsão de Cargas'!D13 -> 15 | F13: Estrela-Triângulo | G13: ='Previsão de Cargas'!M13/3 -> 61.250563 | H13: 5 | I13: ='Previsão de Cargas'!H13*D13/SQRT(3) -> 15.977272 | J13: 3RU11 26-4AB0 | K13: 11 – 16 | L13: 35 | M13: 25 | N13: K1/K2: 3RT10 26-1AQ00 | K3: 3RT10 23-1AQ00 (9 A) | O13: 35 | P13: =1.2*I13*SQRT(3) -> 33.208136 | Q13: Diazed DIII gG (5SB4 11) | R13: 35 | S13: 860 | T13: =IF(S13>H13,"Sim","Não") -> Sim | U13: =IF(R13<=MIN(L13,O13),"Sim","Não") -> Sim
A14: ='Previsão de Cargas'!A14 -> 58 - TUE M9 | B14: ='Previsão de Cargas'!B14 -> CCM2 | C14: Motor M9 | D14: ='Previsão de Cargas'!L14 -> 14.646874 | E14: ='Previsão de Cargas'!D14 -> 10 | F14: Direta | G14: ='Previsão de Cargas'!M14 -> 120.10436 | H14: 5 | I14: ='Previsão de Cargas'!H14*D14 -> 18.308592 | J14: 3RU11 26-4BB0 | K14: 14 – 20 | L14: 35 | M14: 25 | N14: 3RT10 26-1AQ00 | O14: 35 | P14: =1.2*I14 -> 21.97031 | Q14: Diazed DIII gG (5SB4 11) | R14: 35 | S14: 8.5 | T14: =IF(S14>H14,"Sim","Não") -> Sim | U14: =IF(R14<=MIN(L14,O14),"Sim","Não") -> Sim | V14: =MAX(R14:R19) -> 80 | W14: =SUM(D14:D19)-INDEX(D14:D19,MATCH(V14,R14:R19,0)) -> 103.18601 | X14: =V14+W14 -> 183.18601 | Y14: NH1 gG (3NA3 140) | Z14: 200 | AA14: Seccionadora tripolar sob carga 200 A, com base NH1 | AB14: =Z14 -> 200 | AC14: Disjuntor termomagnético tripolar (caixa moldada), no QGBT | AD14: 100
A15: ='Previsão de Cargas'!A15 -> 59 - TUE M10 | C15: Motor M10 | D15: ='Previsão de Cargas'!L15 -> 14.646874 | E15: ='Previsão de Cargas'!D15 -> 10 | F15: Direta | G15: ='Previsão de Cargas'!M15 -> 120.10436 | H15: 5 | I15: ='Previsão de Cargas'!H15*D15 -> 18.308592 | J15: 3RU11 26-4BB0 | K15: 14 – 20 | L15: 35 | M15: 25 | N15: 3RT10 26-1AQ00 | O15: 35 | P15: =1.2*I15 -> 21.97031 | Q15: Diazed DIII gG (5SB4 11) | R15: 35 | S15: 8.5 | T15: =IF(S15>H15,"Sim","Não") -> Sim | U15: =IF(R15<=MIN(L15,O15),"Sim","Não") -> Sim
A16: ='Previsão de Cargas'!A16 -> 60 - TUE M11 | C16: Motor M11 | D16: ='Previsão de Cargas'!L16 -> 14.646874 | E16: ='Previsão de Cargas'!D16 -> 10 | F16: Direta | G16: ='Previsão de Cargas'!M16 -> 120.10436 | H16: 5 | I16: ='Previsão de Cargas'!H16*D16 -> 18.308592 | J16: 3RU11 26-4BB0 | K16: 14 – 20 | L16: 35 | M16: 25 | N16: 3RT10 26-1AQ00 | O16: 35 | P16: =1.2*I16 -> 21.97031 | Q16: Diazed DIII gG (5SB4 11) | R16: 35 | S16: 8.5 | T16: =IF(S16>H16,"Sim","Não") -> Sim | U16: =IF(R16<=MIN(L16,O16),"Sim","Não") -> Sim
A17: ='Previsão de Cargas'!A17 -> 61 - TUE M12 | C17: Motor M12 | D17: ='Previsão de Cargas'!L17 -> 14.646874 | E17: ='Previsão de Cargas'!D17 -> 10 | F17: Direta | G17: ='Previsão de Cargas'!M17 -> 120.10436 | H17: 5 | I17: ='Previsão de Cargas'!H17*D17 -> 18.308592 | J17: 3RU11 26-4BB0 | K17: 14 – 20 | L17: 35 | M17: 25 | N17: 3RT10 26-1AQ00 | O17: 35 | P17: =1.2*I17 -> 21.97031 | Q17: Diazed DIII gG (5SB4 11) | R17: 35 | S17: 8.5 | T17: =IF(S17>H17,"Sim","Não") -> Sim | U17: =IF(R17<=MIN(L17,O17),"Sim","Não") -> Sim
A18: ='Previsão de Cargas'!A18 -> 62 - TUE M13 | C18: Motor M13 | D18: ='Previsão de Cargas'!L18 -> 44.598518 | E18: ='Previsão de Cargas'!D18 -> 30 | F18: Estrela-Triângulo | G18: ='Previsão de Cargas'!M18/3 -> 118.92938 | H18: 5 | I18: ='Previsão de Cargas'!H18*D18/SQRT(3) -> 32.186208 | J18: 3RU11 36-4FB0 | K18: 28 – 40 | L18: 80 | M18: 50 | N18: K1/K2: 3RT10 36-1AQ00 | K3: 3RT10 25-1AQ00 (17 A) | O18: 80 | P18: =1.2*I18*SQRT(3) -> 66.897778 | Q18: NH00 gG (3NA3 824) | R18: 80 | S18: 2900 | T18: =IF(S18>H18,"Sim","Não") -> Sim | U18: =IF(R18<=MIN(L18,O18),"Sim","Não") -> Sim
A19: ='Previsão de Cargas'!A19 -> 63 - TUE M14 | C19: Motor M14 | D19: ='Previsão de Cargas'!L19 -> 44.598518 | E19: ='Previsão de Cargas'!D19 -> 30 | F19: Estrela-Triângulo | G19: ='Previsão de Cargas'!M19/3 -> 118.92938 | H19: 5 | I19: ='Previsão de Cargas'!H19*D19/SQRT(3) -> 32.186208 | J19: 3RU11 36-4FB0 | K19: 28 – 40 | L19: 80 | M19: 50 | N19: K1/K2: 3RT10 36-1AQ00 | K3: 3RT10 25-1AQ00 (17 A) | O19: 80 | P19: =1.2*I19*SQRT(3) -> 66.897778 | Q19: NH00 gG (3NA3 824) | R19: 80 | S19: 2900 | T19: =IF(S19>H19,"Sim","Não") -> Sim | U19: =IF(R19<=MIN(L19,O19),"Sim","Não") -> Sim
A20: ='Previsão de Cargas'!A20 -> 64 - TUE M15 | B20: ='Previsão de Cargas'!B20 -> CCM3 | C20: Motor M15 | D20: ='Previsão de Cargas'!L20 -> 11.960169 | E20: ='Previsão de Cargas'!D20 -> 7.5 | F20: Direta | G20: ='Previsão de Cargas'!M20 -> 87.309234 | H20: 5 | I20: ='Previsão de Cargas'!H20*D20 -> 14.950211 | J20: 3RU11 26-4AB0 | K20: 11 – 16 | L20: 25 | M20: 17 | N20: 3RT10 25-1AQ00 | O20: 25 | P20: =1.2*I20 -> 17.940254 | Q20: Diazed DII gG (5SB2 81) | R20: 25 | S20: 6.6 | T20: =IF(S20>H20,"Sim","Não") -> Sim | U20: =IF(R20<=MIN(L20,O20),"Sim","Não") -> Sim | V20: =MAX(R20:R27) -> 100 | W20: =SUM(D20:D27)-INDEX(D20:D27,MATCH(V20,R20:R27,0)) -> 165.04275 | X20: =V20+W20 -> 265.04275 | Y20: NH2 gG (3NA3 250) | Z20: 300 | AA20: Seccionadora tripolar sob carga 300 A, com base NH2 | AB20: =Z20 -> 300 | AC20: Disjuntor termomagnético tripolar (caixa moldada), no QGBT | AD20: 160
A21: ='Previsão de Cargas'!A21 -> 65 - TUE M16 | C21: Motor M16 | D21: ='Previsão de Cargas'!L21 -> 11.960169 | E21: ='Previsão de Cargas'!D21 -> 7.5 | F21: Direta | G21: ='Previsão de Cargas'!M21 -> 87.309234 | H21: 5 | I21: ='Previsão de Cargas'!H21*D21 -> 14.950211 | J21: 3RU11 26-4AB0 | K21: 11 – 16 | L21: 25 | M21: 17 | N21: 3RT10 25-1AQ00 | O21: 25 | P21: =1.2*I21 -> 17.940254 | Q21: Diazed DII gG (5SB2 81) | R21: 25 | S21: 6.6 | T21: =IF(S21>H21,"Sim","Não") -> Sim | U21: =IF(R21<=MIN(L21,O21),"Sim","Não") -> Sim
A22: ='Previsão de Cargas'!A22 -> 66 - TUE M17 | C22: Motor M17 | D22: ='Previsão de Cargas'!L22 -> 11.960169 | E22: ='Previsão de Cargas'!D22 -> 7.5 | F22: Direta | G22: ='Previsão de Cargas'!M22 -> 87.309234 | H22: 5 | I22: ='Previsão de Cargas'!H22*D22 -> 14.950211 | J22: 3RU11 26-4AB0 | K22: 11 – 16 | L22: 25 | M22: 17 | N22: 3RT10 25-1AQ00 | O22: 25 | P22: =1.2*I22 -> 17.940254 | Q22: Diazed DII gG (5SB2 81) | R22: 25 | S22: 6.6 | T22: =IF(S22>H22,"Sim","Não") -> Sim | U22: =IF(R22<=MIN(L22,O22),"Sim","Não") -> Sim
A23: ='Previsão de Cargas'!A23 -> 67 - TUE M18 | C23: Motor M18 | D23: ='Previsão de Cargas'!L23 -> 11.960169 | E23: ='Previsão de Cargas'!D23 -> 7.5 | F23: Direta | G23: ='Previsão de Cargas'!M23 -> 87.309234 | H23: 5 | I23: ='Previsão de Cargas'!H23*D23 -> 14.950211 | J23: 3RU11 26-4AB0 | K23: 11 – 16 | L23: 25 | M23: 17 | N23: 3RT10 25-1AQ00 | O23: 25 | P23: =1.2*I23 -> 17.940254 | Q23: Diazed DII gG (5SB2 81) | R23: 25 | S23: 6.6 | T23: =IF(S23>H23,"Sim","Não") -> Sim | U23: =IF(R23<=MIN(L23,O23),"Sim","Não") -> Sim
A24: ='Previsão de Cargas'!A24 -> 68 - TUE M19 | C24: Motor M19 | D24: ='Previsão de Cargas'!L24 -> 30.052048 | E24: ='Previsão de Cargas'!D24 -> 20 | F24: Estrela-Triângulo | G24: ='Previsão de Cargas'!M24/3 -> 90.156145 | H24: 5 | I24: ='Previsão de Cargas'!H24*D24/SQRT(3) -> 21.688198 | J24: 3RU11 36-4DB0 | K24: 18 – 25 | L24: 63 | M24: 32 | N24: K1/K2: 3RT10 34-1AQ00 | K3: 3RT10 24-1AQ00 (12 A) | O24: 63 | P24: =1.2*I24*SQRT(3) -> 45.078072 | Q24: Diazed DIII gG (5SB4 21) | R24: 50 | S24: 880 | T24: =IF(S24>H24,"Sim","Não") -> Sim | U24: =IF(R24<=MIN(L24,O24),"Sim","Não") -> Sim
A25: ='Previsão de Cargas'!A25 -> 69 - TUE M20 | C25: Motor M20 | D25: ='Previsão de Cargas'!L25 -> 30.052048 | E25: ='Previsão de Cargas'!D25 -> 20 | F25: Estrela-Triângulo | G25: ='Previsão de Cargas'!M25/3 -> 90.156145 | H25: 5 | I25: ='Previsão de Cargas'!H25*D25/SQRT(3) -> 21.688198 | J25: 3RU11 36-4DB0 | K25: 18 – 25 | L25: 63 | M25: 32 | N25: K1/K2: 3RT10 34-1AQ00 | K3: 3RT10 24-1AQ00 (12 A) | O25: 63 | P25: =1.2*I25*SQRT(3) -> 45.078072 | Q25: Diazed DIII gG (5SB4 21) | R25: 50 | S25: 880 | T25: =IF(S25>H25,"Sim","Não") -> Sim | U25: =IF(R25<=MIN(L25,O25),"Sim","Não") -> Sim
A26: ='Previsão de Cargas'!A26 -> 70 - TUE M21 | C26: Motor M21 | D26: ='Previsão de Cargas'!L26 -> 57.097982 | E26: ='Previsão de Cargas'!D26 -> 40 | F26: Estrela-Triângulo | G26: ='Previsão de Cargas'!M26/3 -> 133.22862 | H26: 5 | I26: ='Previsão de Cargas'!H26*D26/SQRT(3) -> 41.206919 | J26: 3RU11 46-4HB0 | K26: 36 – 50 | L26: 125 | M26: 65 | N26: K1/K2: 3RT10 44-1AQ00 | K3: 3RT10 26-1AQ00 (25 A) | O26: 125 | P26: =1.2*I26*SQRT(3) -> 85.646973 | Q26: NH00 gG (3NA3 830) | R26: 100 | S26: 3000 | T26: =IF(S26>H26,"Sim","Não") -> Sim | U26: =IF(R26<=MIN(L26,O26),"Sim","Não") -> Sim
A27: ='Previsão de Cargas'!A27 -> 71 - TUE M22 | C27: Motor M22 | D27: ='Previsão de Cargas'!L27 -> 57.097982 | E27: ='Previsão de Cargas'!D27 -> 40 | F27: Estrela-Triângulo | G27: ='Previsão de Cargas'!M27/3 -> 133.22862 | H27: 5 | I27: ='Previsão de Cargas'!H27*D27/SQRT(3) -> 41.206919 | J27: 3RU11 46-4HB0 | K27: 36 – 50 | L27: 125 | M27: 65 | N27: K1/K2: 3RT10 44-1AQ00 | K3: 3RT10 26-1AQ00 (25 A) | O27: 125 | P27: =1.2*I27*SQRT(3) -> 85.646973 | Q27: NH00 gG (3NA3 830) | R27: 100 | S27: 3000 | T27: =IF(S27>H27,"Sim","Não") -> Sim | U27: =IF(R27<=MIN(L27,O27),"Sim","Não") -> Sim
A28: ='Previsão de Cargas'!A28 -> 72 - TUE M23 | B28: ='Previsão de Cargas'!B28 -> CCM4 | C28: Motor M23 | D28: ='Previsão de Cargas'!L28 -> 102.28352 | E28: ='Previsão de Cargas'!D28 -> 75 | F28: Soft-starter | G28: ='Previsão de Cargas'!M28 -> 767.12643 | H28: 5 | I28: Soft-starter WEG SSW07 0130 (130 A) – proteção de sobrecarga integrada, ajuste = FS×IN ≈ 128 A – A CONFIRMAR (pesquisa no catálogo WEG) | M28: 150 | N28: 3RT10 55 (150 A) – A CONFIRMAR (slide: mesmo fabricante da soft-starter) | O28: 315 | P28: — | Q28: aR ultrarrápido NH1 (WEG FNH1-400K-A) – A CONFIRMAR no manual SSW07 | R28: 400 | S28: — | T28: N/A: a soft-starter limita a corrente de partida | U28: Verificar coordenação no manual WEG SSW07 | V28: =MAX(R28:R29) -> 400 | W28: =SUM(D28:D29)-INDEX(D28:D29,MATCH(V28,R28:R29,0)) -> 102.28352 | X28: =V28+W28 -> 502.28352 | Y28: NH3 gG (3NA3 372) | Z28: 630 | AA28: Seccionadora tripolar sob carga 630 A, com base NH3 – depende do fusível do 75 HP (A CONFIRMAR) | AB28: =Z28 -> 630 | AC28: Disjuntor termomagnético tripolar (caixa moldada), no QGBT | AD28: 200
A29: ='Previsão de Cargas'!A29 -> 73 - TUE M24 | C29: Motor M24 | D29: ='Previsão de Cargas'!L29 -> 102.28352 | E29: ='Previsão de Cargas'!D29 -> 75 | F29: Soft-starter | G29: ='Previsão de Cargas'!M29 -> 767.12643 | H29: 5 | I29: Soft-starter WEG SSW07 0130 (130 A) – proteção de sobrecarga integrada, ajuste = FS×IN ≈ 128 A – A CONFIRMAR (pesquisa no catálogo WEG) | M29: 150 | N29: 3RT10 55 (150 A) – A CONFIRMAR (slide: mesmo fabricante da soft-starter) | O29: 315 | P29: — | Q29: aR ultrarrápido NH1 (WEG FNH1-400K-A) – A CONFIRMAR no manual SSW07 | R29: 400 | S29: — | T29: N/A: a soft-starter limita a corrente de partida | U29: Verificar coordenação no manual WEG SSW07
A30: ='Previsão de Cargas'!O6 -> Alimentador QD1 | B30: QGBT | C30: QD1 | D30: ='Previsão de Cargas'!U6 -> 120.96539 | AC30: Disjuntor termomagnético tripolar (Tarefa 1) | AD30: 125
A31: ='Previsão de Cargas'!O7 -> Alimentador QD2 | C31: QD2 | D31: ='Previsão de Cargas'!U7 -> 161.92454 | AC31: Disjuntor termomagnético tripolar (Tarefa 1) | AD31: 200
A32: ='Previsão de Cargas'!O8 -> Alimentador QD3 | C32: QD3 | D32: ='Previsão de Cargas'!U8 -> 42.545059 | AC32: Disjuntor termomagnético tripolar (Tarefa 1) | AD32: 50
A33: ='Previsão de Cargas'!O9 -> Alimentador QD4 | C33: QD4 | D33: ='Previsão de Cargas'!U9 -> 53.023454 | AC33: Disjuntor termomagnético tripolar (Tarefa 1) | AD33: 63

Sheet Quadro de Cargas
A2: QUADRO DE CARGAS - | K2: ='Previsão de Cargas'!B1 -> CCM | L2: =_Vnom -> 380 | N2: V
A3: Circuito | B3: Origem | C3: Destino | D3: DADOS DE ENTRADA | J3: FATORES DE CORREÇÃO | L3: CONDUTORES | O3: PROTEÇÃO
D4: Tensão (V) | E4: Carga (HP) | F4: Carga (kW) | G4: F.P. | H4: Carga (kVAr) | I4: Corrente (A) | J4: F.T. | K4: F.A. | L4: Tipo de Isolação | M4: Número condutores por fase | N4: Seção (mm²) | O4: Relé Sobrecarga | Q4: Contator | S4: Fusível | U4: Seccionador | W4: Disjuntor Geral
O5: Modelo | P5: IAJ [A] | Q5: Modelo | R5: Ie [A] | S5: Modelo | T5: IF [A] | U5: Modelo | V5: ICG [A] | W5: Modelo | X5: IDG [A]
A6: ='Previsão de Cargas'!A6 -> 50 - TUE M1 | B6: ='Previsão de Cargas'!B6 -> CCM1 | C6: Motor M1 | D6: =_Vnom -> 380 | E6: ='Previsão de Cargas'!D6 -> 5 | F6: ='Previsão de Cargas'!I6 -> 4.1620112 | G6: ='Previsão de Cargas'!E6 -> 0.77 | H6: ='Previsão de Cargas'!K6 -> 3.4487608 | I6: ='Previsão de Cargas'!L6 -> 8.2123659 | J6: ='Capac.Cond.Corre.'!E4 -> 1 | K6: ='Capac.Cond.Corre.'!G4 -> 0.72 | L6: ='Capac.Cond.Corre.'!J4 -> PVC 0,6/1 kV (Sintenax) | M6: 1 | N6: ='Queda de Tensão'!K4 -> 2.5 | O6: =Proteção!J6 -> 3RU11 16-1KB0 | P6: =Proteção!I6 -> 10.265457 | Q6: =Proteção!N6 -> 3RT10 17-1AQ01 | R6: =Proteção!M6 -> 12 | S6: =Proteção!Q6 -> Diazed DII gG (5SB2 71) | T6: =Proteção!R6 -> 20 | U6: — | V6: — | W6: — | X6: —
A7: ='Previsão de Cargas'!A7 -> 51 - TUE M2 | C7: Motor M2 | D7: =_Vnom -> 380 | E7: ='Previsão de Cargas'!D7 -> 5 | F7: ='Previsão de Cargas'!I7 -> 4.1620112 | G7: ='Previsão de Cargas'!E7 -> 0.77 | H7: ='Previsão de Cargas'!K7 -> 3.4487608 | I7: ='Previsão de Cargas'!L7 -> 8.2123659 | J7: ='Capac.Cond.Corre.'!E5 -> 1 | K7: ='Capac.Cond.Corre.'!G5 -> 0.72 | L7: ='Capac.Cond.Corre.'!J5 -> PVC 0,6/1 kV (Sintenax) | M7: 1 | N7: ='Queda de Tensão'!K5 -> 2.5 | O7: =Proteção!J7 -> 3RU11 16-1KB0 | P7: =Proteção!I7 -> 10.265457 | Q7: =Proteção!N7 -> 3RT10 17-1AQ01 | R7: =Proteção!M7 -> 12 | S7: =Proteção!Q7 -> Diazed DII gG (5SB2 71) | T7: =Proteção!R7 -> 20 | U7: — | V7: — | W7: — | X7: —
A8: ='Previsão de Cargas'!A8 -> 52 - TUE M3 | C8: Motor M3 | D8: =_Vnom -> 380 | E8: ='Previsão de Cargas'!D8 -> 5 | F8: ='Previsão de Cargas'!I8 -> 4.1620112 | G8: ='Previsão de Cargas'!E8 -> 0.77 | H8: ='Previsão de Cargas'!K8 -> 3.4487608 | I8: ='Previsão de Cargas'!L8 -> 8.2123659 | J8: ='Capac.Cond.Corre.'!E6 -> 1 | K8: ='Capac.Cond.Corre.'!G6 -> 0.72 | L8: ='Capac.Cond.Corre.'!J6 -> PVC 0,6/1 kV (Sintenax) | M8: 1 | N8: ='Queda de Tensão'!K6 -> 2.5 | O8: =Proteção!J8 -> 3RU11 16-1KB0 | P8: =Proteção!I8 -> 10.265457 | Q8: =Proteção!N8 -> 3RT10 17-1AQ01 | R8: =Proteção!M8 -> 12 | S8: =Proteção!Q8 -> Diazed DII gG (5SB2 71) | T8: =Proteção!R8 -> 20 | U8: — | V8: — | W8: — | X8: —
A9: ='Previsão de Cargas'!A9 -> 53 - TUE M4 | C9: Motor M4 | D9: =_Vnom -> 380 | E9: ='Previsão de Cargas'!D9 -> 5 | F9: ='Previsão de Cargas'!I9 -> 4.1620112 | G9: ='Previsão de Cargas'!E9 -> 0.77 | H9: ='Previsão de Cargas'!K9 -> 3.4487608 | I9: ='Previsão de Cargas'!L9 -> 8.2123659 | J9: ='Capac.Cond.Corre.'!E7 -> 1 | K9: ='Capac.Cond.Corre.'!G7 -> 0.72 | L9: ='Capac.Cond.Corre.'!J7 -> PVC 0,6/1 kV (Sintenax) | M9: 1 | N9: ='Queda de Tensão'!K7 -> 2.5 | O9: =Proteção!J9 -> 3RU11 16-1KB0 | P9: =Proteção!I9 -> 10.265457 | Q9: =Proteção!N9 -> 3RT10 17-1AQ01 | R9: =Proteção!M9 -> 12 | S9: =Proteção!Q9 -> Diazed DII gG (5SB2 71) | T9: =Proteção!R9 -> 20 | U9: — | V9: — | W9: — | X9: —
A10: ='Previsão de Cargas'!A10 -> 54 - TUE M5 | C10: Motor M5 | D10: =_Vnom -> 380 | E10: ='Previsão de Cargas'!D10 -> 15 | F10: ='Previsão de Cargas'!I10 -> 12.094156 | G10: ='Previsão de Cargas'!E10 -> 0.83 | H10: ='Previsão de Cargas'!K10 -> 8.1273221 | I10: ='Previsão de Cargas'!L10 -> 22.138758 | J10: ='Capac.Cond.Corre.'!E8 -> 1 | K10: ='Capac.Cond.Corre.'!G8 -> 0.72 | L10: ='Capac.Cond.Corre.'!J8 -> PVC 0,6/1 kV (Sintenax) | M10: 2 | N10: ='Queda de Tensão'!K8 -> 4 | O10: =Proteção!J10 -> 3RU11 26-4AB0 | P10: =Proteção!I10 -> 15.977272 | Q10: =Proteção!N10 -> K1/K2: 3RT10 26-1AQ00 | K3: 3RT10 23-1AQ00 (9 A) | R10: =Proteção!M10 -> 25 | S10: =Proteção!Q10 -> Diazed DIII gG (5SB4 11) | T10: =Proteção!R10 -> 35 | U10: — | V10: — | W10: — | X10: —
A11: ='Previsão de Cargas'!A11 -> 55 - TUE M6 | C11: Motor M6 | D11: =_Vnom -> 380 | E11: ='Previsão de Cargas'!D11 -> 15 | F11: ='Previsão de Cargas'!I11 -> 12.094156 | G11: ='Previsão de Cargas'!E11 -> 0.83 | H11: ='Previsão de Cargas'!K11 -> 8.1273221 | I11: ='Previsão de Cargas'!L11 -> 22.138758 | J11: ='Capac.Cond.Corre.'!E9 -> 1 | K11: ='Capac.Cond.Corre.'!G9 -> 0.72 | L11: ='Capac.Cond.Corre.'!J9 -> PVC 0,6/1 kV (Sintenax) | M11: 2 | N11: ='Queda de Tensão'!K9 -> 4 | O11: =Proteção!J11 -> 3RU11 26-4AB0 | P11: =Proteção!I11 -> 15.977272 | Q11: =Proteção!N11 -> K1/K2: 3RT10 26-1AQ00 | K3: 3RT10 23-1AQ00 (9 A) | R11: =Proteção!M11 -> 25 | S11: =Proteção!Q11 -> Diazed DIII gG (5SB4 11) | T11: =Proteção!R11 -> 35 | U11: — | V11: — | W11: — | X11: —
A12: ='Previsão de Cargas'!A12 -> 56 - TUE M7 | C12: Motor M7 | D12: =_Vnom -> 380 | E12: ='Previsão de Cargas'!D12 -> 15 | F12: ='Previsão de Cargas'!I12 -> 12.094156 | G12: ='Previsão de Cargas'!E12 -> 0.83 | H12: ='Previsão de Cargas'!K12 -> 8.1273221 | I12: ='Previsão de Cargas'!L12 -> 22.138758 | J12: ='Capac.Cond.Corre.'!E10 -> 1 | K12: ='Capac.Cond.Corre.'!G10 -> 0.72 | L12: ='Capac.Cond.Corre.'!J10 -> PVC 0,6/1 kV (Sintenax) | M12: 2 | N12: ='Queda de Tensão'!K10 -> 4 | O12: =Proteção!J12 -> 3RU11 26-4AB0 | P12: =Proteção!I12 -> 15.977272 | Q12: =Proteção!N12 -> K1/K2: 3RT10 26-1AQ00 | K3: 3RT10 23-1AQ00 (9 A) | R12: =Proteção!M12 -> 25 | S12: =Proteção!Q12 -> Diazed DIII gG (5SB4 11) | T12: =Proteção!R12 -> 35 | U12: — | V12: — | W12: — | X12: —
A13: ='Previsão de Cargas'!A13 -> 57 - TUE M8 | C13: Motor M8 | D13: =_Vnom -> 380 | E13: ='Previsão de Cargas'!D13 -> 15 | F13: ='Previsão de Cargas'!I13 -> 12.094156 | G13: ='Previsão de Cargas'!E13 -> 0.83 | H13: ='Previsão de Cargas'!K13 -> 8.1273221 | I13: ='Previsão de Cargas'!L13 -> 22.138758 | J13: ='Capac.Cond.Corre.'!E11 -> 1 | K13: ='Capac.Cond.Corre.'!G11 -> 0.72 | L13: ='Capac.Cond.Corre.'!J11 -> PVC 0,6/1 kV (Sintenax) | M13: 2 | N13: ='Queda de Tensão'!K11 -> 4 | O13: =Proteção!J13 -> 3RU11 26-4AB0 | P13: =Proteção!I13 -> 15.977272 | Q13: =Proteção!N13 -> K1/K2: 3RT10 26-1AQ00 | K3: 3RT10 23-1AQ00 (9 A) | R13: =Proteção!M13 -> 25 | S13: =Proteção!Q13 -> Diazed DIII gG (5SB4 11) | T13: =Proteção!R13 -> 35 | U13: — | V13: — | W13: — | X13: —
A14: ='Previsão de Cargas'!A14 -> 58 - TUE M9 | B14: ='Previsão de Cargas'!B14 -> CCM2 | C14: Motor M9 | D14: =_Vnom -> 380 | E14: ='Previsão de Cargas'!D14 -> 10 | F14: ='Previsão de Cargas'!I14 -> 8.0978261 | G14: ='Previsão de Cargas'!E14 -> 0.84 | H14: ='Previsão de Cargas'!K14 -> 5.2306789 | I14: ='Previsão de Cargas'!L14 -> 14.646874 | J14: ='Capac.Cond.Corre.'!E12 -> 1 | K14: ='Capac.Cond.Corre.'!G12 -> 0.72 | L14: ='Capac.Cond.Corre.'!J12 -> PVC 0,6/1 kV (Sintenax) | M14: 1 | N14: ='Queda de Tensão'!K12 -> 4 | O14: =Proteção!J14 -> 3RU11 26-4BB0 | P14: =Proteção!I14 -> 18.308592 | Q14: =Proteção!N14 -> 3RT10 26-1AQ00 | R14: =Proteção!M14 -> 25 | S14: =Proteção!Q14 -> Diazed DIII gG (5SB4 11) | T14: =Proteção!R14 -> 35 | U14: — | V14: — | W14: — | X14: —
A15: ='Previsão de Cargas'!A15 -> 59 - TUE M10 | C15: Motor M10 | D15: =_Vnom -> 380 | E15: ='Previsão de Cargas'!D15 -> 10 | F15: ='Previsão de Cargas'!I15 -> 8.0978261 | G15: ='Previsão de Cargas'!E15 -> 0.84 | H15: ='Previsão de Cargas'!K15 -> 5.2306789 | I15: ='Previsão de Cargas'!L15 -> 14.646874 | J15: ='Capac.Cond.Corre.'!E13 -> 1 | K15: ='Capac.Cond.Corre.'!G13 -> 0.72 | L15: ='Capac.Cond.Corre.'!J13 -> PVC 0,6/1 kV (Sintenax) | M15: 1 | N15: ='Queda de Tensão'!K13 -> 4 | O15: =Proteção!J15 -> 3RU11 26-4BB0 | P15: =Proteção!I15 -> 18.308592 | Q15: =Proteção!N15 -> 3RT10 26-1AQ00 | R15: =Proteção!M15 -> 25 | S15: =Proteção!Q15 -> Diazed DIII gG (5SB4 11) | T15: =Proteção!R15 -> 35 | U15: — | V15: — | W15: — | X15: —
A16: ='Previsão de Cargas'!A16 -> 60 - TUE M11 | C16: Motor M11 | D16: =_Vnom -> 380 | E16: ='Previsão de Cargas'!D16 -> 10 | F16: ='Previsão de Cargas'!I16 -> 8.0978261 | G16: ='Previsão de Cargas'!E16 -> 0.84 | H16: ='Previsão de Cargas'!K16 -> 5.2306789 | I16: ='Previsão de Cargas'!L16 -> 14.646874 | J16: ='Capac.Cond.Corre.'!E14 -> 1 | K16: ='Capac.Cond.Corre.'!G14 -> 0.72 | L16: ='Capac.Cond.Corre.'!J14 -> PVC 0,6/1 kV (Sintenax) | M16: 1 | N16: ='Queda de Tensão'!K14 -> 4 | O16: =Proteção!J16 -> 3RU11 26-4BB0 | P16: =Proteção!I16 -> 18.308592 | Q16: =Proteção!N16 -> 3RT10 26-1AQ00 | R16: =Proteção!M16 -> 25 | S16: =Proteção!Q16 -> Diazed DIII gG (5SB4 11) | T16: =Proteção!R16 -> 35 | U16: — | V16: — | W16: — | X16: —
A17: ='Previsão de Cargas'!A17 -> 61 - TUE M12 | C17: Motor M12 | D17: =_Vnom -> 380 | E17: ='Previsão de Cargas'!D17 -> 10 | F17: ='Previsão de Cargas'!I17 -> 8.0978261 | G17: ='Previsão de Cargas'!E17 -> 0.84 | H17: ='Previsão de Cargas'!K17 -> 5.2306789 | I17: ='Previsão de Cargas'!L17 -> 14.646874 | J17: ='Capac.Cond.Corre.'!E15 -> 1 | K17: ='Capac.Cond.Corre.'!G15 -> 0.72 | L17: ='Capac.Cond.Corre.'!J15 -> PVC 0,6/1 kV (Sintenax) | M17: 1 | N17: ='Queda de Tensão'!K15 -> 4 | O17: =Proteção!J17 -> 3RU11 26-4BB0 | P17: =Proteção!I17 -> 18.308592 | Q17: =Proteção!N17 -> 3RT10 26-1AQ00 | R17: =Proteção!M17 -> 25 | S17: =Proteção!Q17 -> Diazed DIII gG (5SB4 11) | T17: =Proteção!R17 -> 35 | U17: — | V17: — | W17: — | X17: —
A18: ='Previsão de Cargas'!A18 -> 62 - TUE M13 | C18: Motor M13 | D18: =_Vnom -> 380 | E18: ='Previsão de Cargas'!D18 -> 30 | F18: ='Previsão de Cargas'!I18 -> 23.776596 | G18: ='Previsão de Cargas'!E18 -> 0.81 | H18: ='Previsão de Cargas'!K18 -> 17.213958 | I18: ='Previsão de Cargas'!L18 -> 44.598518 | J18: ='Capac.Cond.Corre.'!E16 -> 1 | K18: ='Capac.Cond.Corre.'!G16 -> 0.72 | L18: ='Capac.Cond.Corre.'!J16 -> PVC 0,6/1 kV (Sintenax) | M18: 2 | N18: ='Queda de Tensão'!K16 -> 16 | O18: =Proteção!J18 -> 3RU11 36-4FB0 | P18: =Proteção!I18 -> 32.186208 | Q18: =Proteção!N18 -> K1/K2: 3RT10 36-1AQ00 | K3: 3RT10 25-1AQ00 (17 A) | R18: =Proteção!M18 -> 50 | S18: =Proteção!Q18 -> NH00 gG (3NA3 824) | T18: =Proteção!R18 -> 80 | U18: — | V18: — | W18: — | X18: —
A19: ='Previsão de Cargas'!A19 -> 63 - TUE M14 | C19: Motor M14 | D19: =_Vnom -> 380 | E19: ='Previsão de Cargas'!D19 -> 30 | F19: ='Previsão de Cargas'!I19 -> 23.776596 | G19: ='Previsão de Cargas'!E19 -> 0.81 | H19: ='Previsão de Cargas'!K19 -> 17.213958 | I19: ='Previsão de Cargas'!L19 -> 44.598518 | J19: ='Capac.Cond.Corre.'!E17 -> 1 | K19: ='Capac.Cond.Corre.'!G17 -> 0.72 | L19: ='Capac.Cond.Corre.'!J17 -> PVC 0,6/1 kV (Sintenax) | M19: 2 | N19: ='Queda de Tensão'!K17 -> 16 | O19: =Proteção!J19 -> 3RU11 36-4FB0 | P19: =Proteção!I19 -> 32.186208 | Q19: =Proteção!N19 -> K1/K2: 3RT10 36-1AQ00 | K3: 3RT10 25-1AQ00 (17 A) | R19: =Proteção!M19 -> 50 | S19: =Proteção!Q19 -> NH00 gG (3NA3 824) | T19: =Proteção!R19 -> 80 | U19: — | V19: — | W19: — | X19: —
A20: ='Previsão de Cargas'!A20 -> 64 - TUE M15 | B20: ='Previsão de Cargas'!B20 -> CCM3 | C20: Motor M15 | D20: =_Vnom -> 380 | E20: ='Previsão de Cargas'!D20 -> 7.5 | F20: ='Previsão de Cargas'!I20 -> 6.1401099 | G20: ='Previsão de Cargas'!E20 -> 0.78 | H20: ='Previsão de Cargas'!K20 -> 4.9260961 | I20: ='Previsão de Cargas'!L20 -> 11.960169 | J20: ='Capac.Cond.Corre.'!E18 -> 1 | K20: ='Capac.Cond.Corre.'!G18 -> 0.72 | L20: ='Capac.Cond.Corre.'!J18 -> PVC 0,6/1 kV (Sintenax) | M20: 1 | N20: ='Queda de Tensão'!K18 -> 2.5 | O20: =Proteção!J20 -> 3RU11 26-4AB0 | P20: =Proteção!I20 -> 14.950211 | Q20: =Proteção!N20 -> 3RT10 25-1AQ00 | R20: =Proteção!M20 -> 17 | S20: =Proteção!Q20 -> Diazed DII gG (5SB2 81) | T20: =Proteção!R20 -> 25 | U20: — | V20: — | W20: — | X20: —
A21: ='Previsão de Cargas'!A21 -> 65 - TUE M16 | C21: Motor M16 | D21: =_Vnom -> 380 | E21: ='Previsão de Cargas'!D21 -> 7.5 | F21: ='Previsão de Cargas'!I21 -> 6.1401099 | G21: ='Previsão de Cargas'!E21 -> 0.78 | H21: ='Previsão de Cargas'!K21 -> 4.9260961 | I21: ='Previsão de Cargas'!L21 -> 11.960169 | J21: ='Capac.Cond.Corre.'!E19 -> 1 | K21: ='Capac.Cond.Corre.'!G19 -> 0.72 | L21: ='Capac.Cond.Corre.'!J19 -> PVC 0,6/1 kV (Sintenax) | M21: 1 | N21: ='Queda de Tensão'!K19 -> 2.5 | O21: =Proteção!J21 -> 3RU11 26-4AB0 | P21: =Proteção!I21 -> 14.950211 | Q21: =Proteção!N21 -> 3RT10 25-1AQ00 | R21: =Proteção!M21 -> 17 | S21: =Proteção!Q21 -> Diazed DII gG (5SB2 81) | T21: =Proteção!R21 -> 25 | U21: — | V21: — | W21: — | X21: —
A22: ='Previsão de Cargas'!A22 -> 66 - TUE M17 | C22: Motor M17 | D22: =_Vnom -> 380 | E22: ='Previsão de Cargas'!D22 -> 7.5 | F22: ='Previsão de Cargas'!I22 -> 6.1401099 | G22: ='Previsão de Cargas'!E22 -> 0.78 | H22: ='Previsão de Cargas'!K22 -> 4.9260961 | I22: ='Previsão de Cargas'!L22 -> 11.960169 | J22: ='Capac.Cond.Corre.'!E20 -> 1 | K22: ='Capac.Cond.Corre.'!G20 -> 0.72 | L22: ='Capac.Cond.Corre.'!J20 -> PVC 0,6/1 kV (Sintenax) | M22: 1 | N22: ='Queda de Tensão'!K20 -> 2.5 | O22: =Proteção!J22 -> 3RU11 26-4AB0 | P22: =Proteção!I22 -> 14.950211 | Q22: =Proteção!N22 -> 3RT10 25-1AQ00 | R22: =Proteção!M22 -> 17 | S22: =Proteção!Q22 -> Diazed DII gG (5SB2 81) | T22: =Proteção!R22 -> 25 | U22: — | V22: — | W22: — | X22: —
A23: ='Previsão de Cargas'!A23 -> 67 - TUE M18 | C23: Motor M18 | D23: =_Vnom -> 380 | E23: ='Previsão de Cargas'!D23 -> 7.5 | F23: ='Previsão de Cargas'!I23 -> 6.1401099 | G23: ='Previsão de Cargas'!E23 -> 0.78 | H23: ='Previsão de Cargas'!K23 -> 4.9260961 | I23: ='Previsão de Cargas'!L23 -> 11.960169 | J23: ='Capac.Cond.Corre.'!E21 -> 1 | K23: ='Capac.Cond.Corre.'!G21 -> 0.72 | L23: ='Capac.Cond.Corre.'!J21 -> PVC 0,6/1 kV (Sintenax) | M23: 1 | N23: ='Queda de Tensão'!K21 -> 2.5 | O23: =Proteção!J23 -> 3RU11 26-4AB0 | P23: =Proteção!I23 -> 14.950211 | Q23: =Proteção!N23 -> 3RT10 25-1AQ00 | R23: =Proteção!M23 -> 17 | S23: =Proteção!Q23 -> Diazed DII gG (5SB2 81) | T23: =Proteção!R23 -> 25 | U23: — | V23: — | W23: — | X23: —
A24: ='Previsão de Cargas'!A24 -> 68 - TUE M19 | C24: Motor M19 | D24: =_Vnom -> 380 | E24: ='Previsão de Cargas'!D24 -> 20 | F24: ='Previsão de Cargas'!I24 -> 16.021505 | G24: ='Previsão de Cargas'!E24 -> 0.81 | H24: ='Previsão de Cargas'!K24 -> 11.59937 | I24: ='Previsão de Cargas'!L24 -> 30.052048 | J24: ='Capac.Cond.Corre.'!E22 -> 1 | K24: ='Capac.Cond.Corre.'!G22 -> 0.72 | L24: ='Capac.Cond.Corre.'!J22 -> PVC 0,6/1 kV (Sintenax) | M24: 2 | N24: ='Queda de Tensão'!K22 -> 6 | O24: =Proteção!J24 -> 3RU11 36-4DB0 | P24: =Proteção!I24 -> 21.688198 | Q24: =Proteção!N24 -> K1/K2: 3RT10 34-1AQ00 | K3: 3RT10 24-1AQ00 (12 A) | R24: =Proteção!M24 -> 32 | S24: =Proteção!Q24 -> Diazed DIII gG (5SB4 21) | T24: =Proteção!R24 -> 50 | U24: — | V24: — | W24: — | X24: —
A25: ='Previsão de Cargas'!A25 -> 69 - TUE M20 | C25: Motor M20 | D25: =_Vnom -> 380 | E25: ='Previsão de Cargas'!D25 -> 20 | F25: ='Previsão de Cargas'!I25 -> 16.021505 | G25: ='Previsão de Cargas'!E25 -> 0.81 | H25: ='Previsão de Cargas'!K25 -> 11.59937 | I25: ='Previsão de Cargas'!L25 -> 30.052048 | J25: ='Capac.Cond.Corre.'!E23 -> 1 | K25: ='Capac.Cond.Corre.'!G23 -> 0.72 | L25: ='Capac.Cond.Corre.'!J23 -> PVC 0,6/1 kV (Sintenax) | M25: 2 | N25: ='Queda de Tensão'!K23 -> 6 | O25: =Proteção!J25 -> 3RU11 36-4DB0 | P25: =Proteção!I25 -> 21.688198 | Q25: =Proteção!N25 -> K1/K2: 3RT10 34-1AQ00 | K3: 3RT10 24-1AQ00 (12 A) | R25: =Proteção!M25 -> 32 | S25: =Proteção!Q25 -> Diazed DIII gG (5SB4 21) | T25: =Proteção!R25 -> 50 | U25: — | V25: — | W25: — | X25: —
A26: ='Previsão de Cargas'!A26 -> 70 - TUE M21 | C26: Motor M21 | D26: =_Vnom -> 380 | E26: ='Previsão de Cargas'!D26 -> 40 | F26: ='Previsão de Cargas'!I26 -> 31.567797 | G26: ='Previsão de Cargas'!E26 -> 0.84 | H26: ='Previsão de Cargas'!K26 -> 20.390782 | I26: ='Previsão de Cargas'!L26 -> 57.097982 | J26: ='Capac.Cond.Corre.'!E24 -> 1 | K26: ='Capac.Cond.Corre.'!G24 -> 0.72 | L26: ='Capac.Cond.Corre.'!J24 -> PVC 0,6/1 kV (Sintenax) | M26: 2 | N26: ='Queda de Tensão'!K24 -> 16 | O26: =Proteção!J26 -> 3RU11 46-4HB0 | P26: =Proteção!I26 -> 41.206919 | Q26: =Proteção!N26 -> K1/K2: 3RT10 44-1AQ00 | K3: 3RT10 26-1AQ00 (25 A) | R26: =Proteção!M26 -> 65 | S26: =Proteção!Q26 -> NH00 gG (3NA3 830) | T26: =Proteção!R26 -> 100 | U26: — | V26: — | W26: — | X26: —
A27: ='Previsão de Cargas'!A27 -> 71 - TUE M22 | C27: Motor M22 | D27: =_Vnom -> 380 | E27: ='Previsão de Cargas'!D27 -> 40 | F27: ='Previsão de Cargas'!I27 -> 31.567797 | G27: ='Previsão de Cargas'!E27 -> 0.84 | H27: ='Previsão de Cargas'!K27 -> 20.390782 | I27: ='Previsão de Cargas'!L27 -> 57.097982 | J27: ='Capac.Cond.Corre.'!E25 -> 1 | K27: ='Capac.Cond.Corre.'!G25 -> 0.72 | L27: ='Capac.Cond.Corre.'!J25 -> PVC 0,6/1 kV (Sintenax) | M27: 2 | N27: ='Queda de Tensão'!K25 -> 16 | O27: =Proteção!J27 -> 3RU11 46-4HB0 | P27: =Proteção!I27 -> 41.206919 | Q27: =Proteção!N27 -> K1/K2: 3RT10 44-1AQ00 | K3: 3RT10 26-1AQ00 (25 A) | R27: =Proteção!M27 -> 65 | S27: =Proteção!Q27 -> NH00 gG (3NA3 830) | T27: =Proteção!R27 -> 100 | U27: — | V27: — | W27: — | X27: —
A28: ='Previsão de Cargas'!A28 -> 72 - TUE M23 | B28: ='Previsão de Cargas'!B28 -> CCM4 | C28: Motor M23 | D28: =_Vnom -> 380 | E28: ='Previsão de Cargas'!D28 -> 75 | F28: ='Previsão de Cargas'!I28 -> 58.569182 | G28: ='Previsão de Cargas'!E28 -> 0.87 | H28: ='Previsão de Cargas'!K28 -> 33.192685 | I28: ='Previsão de Cargas'!L28 -> 102.28352 | J28: ='Capac.Cond.Corre.'!E26 -> 1 | K28: ='Capac.Cond.Corre.'!G26 -> 0.88 | L28: ='Capac.Cond.Corre.'!J26 -> EPR 0,6/1 kV (Afumex) | M28: 1 | N28: ='Queda de Tensão'!K26 -> 35 | O28: =Proteção!I28 -> Soft-starter WEG SSW07 0130 (130 A) – proteção de sobrecarga integrada, ajuste = FS×IN ≈ 128 A – A CONFIRMAR (pesquisa no catálogo WEG) | Q28: =Proteção!N28 -> 3RT10 55 (150 A) – A CONFIRMAR (slide: mesmo fabricante da soft-starter) | R28: =Proteção!M28 -> 150 | S28: =Proteção!Q28 -> aR ultrarrápido NH1 (WEG FNH1-400K-A) – A CONFIRMAR no manual SSW07 | T28: =Proteção!R28 -> 400 | U28: Seccionadora conforme fusível – A CONFIRMAR | V28: =Proteção!R28 -> 400 | W28: — | X28: —
