Workbook

Sheet Luminotécnico
A1: PROJETO LUMINOTÉCNICO
A2: Item | B2: Ambiente | C2: Refletâncias | F2: Dimensões | L2: Iluminância (E) [lux] | M2: Índice local (RCR) | N2: Índice local (k) | O2: Lâmpada | Z2: Luminária | AD2: Fator de Utilização (µ) | AE2: Fator de Depreciação (d) | AF2: Fluxo Luminoso Total do ambiente (lm) | AG2: Número de Luminárias (NL) [Unid.] | AH2: N° luminárias na largura (Ny) [Unid.] | AI2: N° luminárias no comprimento (Nx) [Unid.] | AJ2: Dist. Lamp.-Lamp. (DLL(x)) | AK2: Dist. Lamp.-Lamp. (DLL(y)) | AL2: Dist. Lamp.-Pare. (DLP(x)) | AM2: Dist. Lamp.-Pare. (DLP(y)) | AN2: Potência Ativa total (P) [W] | AO2: Potência Aparente total (S) [VA]
C3: Teto (%) | D3: Parede (%) | E3: Piso (%) | F3: Largura [m] | G3: Comprimento [m] | H3: Pé direito (Pd) [m] | I3: Plano de trabalho (hpt) [m] | J3: Distância entre luminária e teto (hs) [m] | K3: h | O3: Tipo de Lâmpada | P3: Fabricante | Q3: Código do Modelo do Fabricante | R3: Fluxo Luminoso [lm] | S3: IRC [%] | T3: Temperatura de cor [K] | U3: Vida útil [h] | V3: Potência Lâmpada [W] | W3: Perdas Reator [W] | X3: Fator de Potência | Y3: Link do catálogo | Z3: Fabricante | AA3: Modelo | AB3: N° Lâmpadas [Unid.] | AC3: Link do catálogo
A4: AREA FABRIL
A5: 1 | B5: Tornear e Chanfrar | C5: 0.7 | D5: 0.5 | E5: 0.1 | F5: 9 | G5: 16.2 | H5: 6 | I5: 1 | J5: 1 | K5: =IF(F5="", "", H5 - I5 - J5) -> 4 | L5: 500 | M5: =IF(F5="", "", 5 * K5 * (F5 + G5) / (F5 * G5)) -> 3.4567901 | N5: =IF(F5="", "", (F5 * G5) / (K5 * (F5 + G5))) -> 1.4464286 | O5: Luminária LED High Bay UFO | P5: LUMICENTER | Q5: LHB60-S12000850FW | R5: 12620 | S5: 80 | T5: 5000 | U5: 100000 | V5: 78.7 | W5: 0 | X5: 0.99 | Y5: https://lumicenter.com/produtos/lhb60-s | Z5: LUMICENTER | AA5: LHB60-S12000850FW | AB5: 1 | AC5: https://lumicenter.com/produtos/lhb60-s | AD5: 0.76 | AE5: 0.7 | AF5: =IF(F5="", "", IFERROR((L5 * F5 * G5) / (AD5 * AE5), "")) -> 137030.08 | AG5: =ROUNDUP(AF5/(R5*AB5),0) -> 11 | AH5: 3 | AI5: 4 | AJ5: =IF(F5="", "", IFERROR(G5 / AI5, "")) -> 4.05 | AK5: =IF(F5="", "", IFERROR(F5 / AH5, "")) -> 3 | AL5: =IF(F5="", "", IFERROR(AJ5 / 2, "")) -> 2.025 | AM5: =IF(F5="", "", IFERROR(AK5 / 2, "")) -> 1.5 | AN5: =AH5*AI5*AB5*(V5+W5) -> 944.4 | AO5: =IF(F5="", "", IFERROR(AN5 / X5, "")) -> 953.93939
A6: 2 | B6: Polimento | C6: 0.7 | D6: 0.5 | E6: 0.1 | F6: 8.2 | G6: 16.2 | H6: 6 | I6: 1 | J6: 1 | K6: =IF(F6="", "", H6 - I6 - J6) -> 4 | L6: 750 | M6: =IF(F6="", "", 5 * K6 * (F6 + G6) / (F6 * G6)) -> 3.6735923 | N6: =IF(F6="", "", (F6 * G6) / (K6 * (F6 + G6))) -> 1.3610656 | O6: Luminária LED High Bay UFO | P6: LUMICENTER | Q6: LHB60-S12000850FW | R6: 12620 | S6: 80 | T6: 5000 | U6: 100000 | V6: 78.7 | W6: 0 | X6: 0.99 | Y6: https://lumicenter.com/produtos/lhb60-s | Z6: LUMICENTER | AA6: LHB60-S12000850FW | AB6: 1 | AC6: https://lumicenter.com/produtos/lhb60-s | AD6: 0.74 | AE6: 0.7 | AF6: =IF(F6="", "", IFERROR((L6 * F6 * G6) / (AD6 * AE6), "")) -> 192335.91 | AG6: =ROUNDUP(AF6/(R6*AB6),0) -> 16 | AH6: 3 | AI6: 6 | AJ6: =IF(F6="", "", IFERROR(G6 / AI6, "")) -> 2.7 | AK6: =IF(F6="", "", IFERROR(F6 / AH6, "")) -> 2.7333333 | AL6: =IF(F6="", "", IFERROR(AJ6 / 2, "")) -> 1.35 | AM6: =IF(F6="", "", IFERROR(AK6 / 2, "")) -> 1.3666667 | AN6: =AH6*AI6*AB6*(V6+W6) -> 1416.6 | AO6: =IF(F6="", "", IFERROR(AN6 / X6, "")) -> 1430.9091
A7: 3 | B7: Colagem e montagem | C7: 0.7 | D7: 0.5 | E7: 0.1 | F7: 9 | G7: 16.6 | H7: 6 | I7: 1 | J7: 1 | K7: =IF(F7="", "", H7 - I7 - J7) -> 4 | L7: 300 | M7: =IF(F7="", "", 5 * K7 * (F7 + G7) / (F7 * G7)) -> 3.4270415 | N7: =IF(F7="", "", (F7 * G7) / (K7 * (F7 + G7))) -> 1.4589844 | O7: Luminária LED High Bay UFO | P7: LUMICENTER | Q7: LHB60-S12000850FW | R7: 12620 | S7: 80 | T7: 5000 | U7: 100000 | V7: 78.7 | W7: 0 | X7: 0.99 | Y7: https://lumicenter.com/produtos/lhb60-s | Z7: LUMICENTER | AA7: LHB60-S12000850FW | AB7: 1 | AC7: https://lumicenter.com/produtos/lhb60-s | AD7: 0.76 | AE7: 0.7 | AF7: =IF(F7="", "", IFERROR((L7 * F7 * G7) / (AD7 * AE7), "")) -> 84248.12 | AG7: =ROUNDUP(AF7/(R7*AB7),0) -> 7 | AH7: 2 | AI7: 4 | AJ7: =IF(F7="", "", IFERROR(G7 / AI7, "")) -> 4.15 | AK7: =IF(F7="", "", IFERROR(F7 / AH7, "")) -> 4.5 | AL7: =IF(F7="", "", IFERROR(AJ7 / 2, "")) -> 2.075 | AM7: =IF(F7="", "", IFERROR(AK7 / 2, "")) -> 2.25 | AN7: =AH7*AI7*AB7*(V7+W7) -> 629.6 | AO7: =IF(F7="", "", IFERROR(AN7 / X7, "")) -> 635.9596
A8: 4 | B8: Sistemas de Serra | C8: 0.7 | D8: 0.5 | E8: 0.1 | F8: 8.15 | G8: 16.7 | H8: 6 | I8: 1 | J8: 1 | K8: =IF(F8="", "", H8 - I8 - J8) -> 4 | L8: 300 | M8: =IF(F8="", "", 5 * K8 * (F8 + G8) / (F8 * G8)) -> 3.6515925 | N8: =IF(F8="", "", (F8 * G8) / (K8 * (F8 + G8))) -> 1.3692656 | O8: Luminária LED High Bay UFO | P8: LUMICENTER | Q8: LHB60-S12000850FW | R8: 12620 | S8: 80 | T8: 5000 | U8: 100000 | V8: 78.7 | W8: 0 | X8: 0.99 | Y8: https://lumicenter.com/produtos/lhb60-s | Z8: LUMICENTER | AA8: LHB60-S12000850FW | AB8: 1 | AC8: https://lumicenter.com/produtos/lhb60-s | AD8: 0.74 | AE8: 0.7 | AF8: =IF(F8="", "", IFERROR((L8 * F8 * G8) / (AD8 * AE8), "")) -> 78825.29 | AG8: =ROUNDUP(AF8/(R8*AB8),0) -> 7 | AH8: 2 | AI8: 4 | AJ8: =IF(F8="", "", IFERROR(G8 / AI8, "")) -> 4.175 | AK8: =IF(F8="", "", IFERROR(F8 / AH8, "")) -> 4.075 | AL8: =IF(F8="", "", IFERROR(AJ8 / 2, "")) -> 2.0875 | AM8: =IF(F8="", "", IFERROR(AK8 / 2, "")) -> 2.0375 | AN8: =AH8*AI8*AB8*(V8+W8) -> 629.6 | AO8: =IF(F8="", "", IFERROR(AN8 / X8, "")) -> 635.9596
A9: 5 | B9: Inspeção Final | C9: 0.7 | D9: 0.5 | E9: 0.1 | F9: 7.15 | G9: 13.45 | H9: 6 | I9: 1 | J9: 1 | K9: =IF(F9="", "", H9 - I9 - J9) -> 4 | L9: 1000 | M9: =IF(F9="", "", 5 * K9 * (F9 + G9) / (F9 * G9)) -> 4.2841916 | N9: =IF(F9="", "", (F9 * G9) / (K9 * (F9 + G9))) -> 1.1670813 | O9: Luminária LED High Bay UFO | P9: LUMICENTER | Q9: LHB60-S12000850FW | R9: 12620 | S9: 80 | T9: 5000 | U9: 100000 | V9: 78.7 | W9: 0 | X9: 0.99 | Y9: https://lumicenter.com/produtos/lhb60-s | Z9: LUMICENTER | AA9: LHB60-S12000850FW | AB9: 1 | AC9: https://lumicenter.com/produtos/lhb60-s | AD9: 0.69 | AE9: 0.7 | AF9: =IF(F9="", "", IFERROR((L9 * F9 * G9) / (AD9 * AE9), "")) -> 199104.55 | AG9: =ROUNDUP(AF9/(R9*AB9),0) -> 16 | AH9: 3 | AI9: 7 | AJ9: =IF(F9="", "", IFERROR(G9 / AI9, "")) -> 1.9214286 | AK9: =IF(F9="", "", IFERROR(F9 / AH9, "")) -> 2.3833333 | AL9: =IF(F9="", "", IFERROR(AJ9 / 2, "")) -> 0.96071429 | AM9: =IF(F9="", "", IFERROR(AK9 / 2, "")) -> 1.1916667 | AN9: =AH9*AI9*AB9*(V9+W9) -> 1652.7 | AO9: =IF(F9="", "", IFERROR(AN9 / X9, "")) -> 1669.3939
A10: AREA COMERCIAL
A11: 6 | B11: Sala de Estar | C11: 0.7 | D11: 0.5 | E11: 0.1 | F11: 5.9 | G11: 9.2 | H11: 3 | I11: 0.7 | J11: 0.5 | K11: =IF(F11="", "", H11 - I11 - J11) -> 1.8 | L11: 200 | M11: =IF(F11="", "", 5 * K11 * (F11 + G11) / (F11 * G11)) -> 2.5036846 | N11: =IF(F11="", "", (F11 * G11) / (K11 * (F11 + G11))) -> 1.9970567 | O11: Luminária LED | P11: LUMICENTER | Q11: LHT44-S4000840 | R11: 4000 | S11: 80 | T11: 4000 | U11: 50000 | V11: 40 | W11: 0 | X11: 0.99 | Y11: https://lumicenter.com/produtos/lht44-s | Z11: LUMICENTER | AA11: LHT44-S4000840 | AB11: 1 | AC11: https://lumicenter.com/produtos/lht44-s | AD11: 0.82 | AE11: 0.85 | AF11: =IF(F11="", "", IFERROR((L11 * F11 * G11) / (AD11 * AE11), "")) -> 15575.323 | AG11: =IF(F11="", "", IFERROR(ROUND(AF11 / (R11 * AB11), 0), "")) -> 4 | AH11: 2 | AI11: 3 | AJ11: =IF(F11="", "", IFERROR(G11 / AI11, "")) -> 3.0666667 | AK11: =IF(F11="", "", IFERROR(F11 / AH11, "")) -> 2.95 | AL11: =IF(F11="", "", IFERROR(AJ11 / 2, "")) -> 1.5333333 | AM11: =IF(F11="", "", IFERROR(AK11 / 2, "")) -> 1.475 | AN11: =AH11*AI11*AB11*(V11+W11) -> 240 | AO11: =IF(F11="", "", IFERROR(AN11 / X11, "")) -> 242.42424
A12: 7 | B12: Sala de reuniões | C12: 0.7 | D12: 0.5 | E12: 0.1 | F12: 5.5 | G12: 7.7 | H12: 3 | I12: 0.7 | J12: 0.5 | K12: =IF(F12="", "", H12 - I12 - J12) -> 1.8 | L12: 500 | M12: =IF(F12="", "", 5 * K12 * (F12 + G12) / (F12 * G12)) -> 2.8051948 | N12: =IF(F12="", "", (F12 * G12) / (K12 * (F12 + G12))) -> 1.7824074 | O12: Luminária LED | P12: LUMICENTER | Q12: LHT44-S4000840 | R12: 4000 | S12: 80 | T12: 4000 | U12: 50000 | V12: 40 | W12: 0 | X12: 0.99 | Y12: https://lumicenter.com/produtos/lht44-s | Z12: LUMICENTER | AA12: LHT44-S4000840 | AB12: 1 | AC12: https://lumicenter.com/produtos/lht44-s | AD12: 0.79 | AE12: 0.85 | AF12: =IF(F12="", "", IFERROR((L12 * F12 * G12) / (AD12 * AE12), "")) -> 31533.879 | AG12: =IF(F12="", "", IFERROR(ROUND(AF12 / (R12 * AB12), 0), "")) -> 8 | AH12: 3 | AI12: 3 | AJ12: =IF(F12="", "", IFERROR(G12 / AI12, "")) -> 2.5666667 | AK12: =IF(F12="", "", IFERROR(F12 / AH12, "")) -> 1.8333333 | AL12: =IF(F12="", "", IFERROR(AJ12 / 2, "")) -> 1.2833333 | AM12: =IF(F12="", "", IFERROR(AK12 / 2, "")) -> 0.91666667 | AN12: =AH12*AI12*AB12*(V12+W12) -> 360 | AO12: =IF(F12="", "", IFERROR(AN12 / X12, "")) -> 363.63636
A13: 8 | B13: Recepção | C13: 0.7 | D13: 0.5 | E13: 0.1 | F13: 4 | G13: 4.8 | H13: 3 | I13: 0.7 | J13: 0.5 | K13: =IF(F13="", "", H13 - I13 - J13) -> 1.8 | L13: 300 | M13: =IF(F13="", "", 5 * K13 * (F13 + G13) / (F13 * G13)) -> 4.125 | N13: =IF(F13="", "", (F13 * G13) / (K13 * (F13 + G13))) -> 1.2121212 | O13: Luminária LED | P13: LUMICENTER | Q13: LHT44-S4000840 | R13: 4000 | S13: 80 | T13: 4000 | U13: 50000 | V13: 40 | W13: 0 | X13: 0.99 | Y13: https://lumicenter.com/produtos/lht44-s | Z13: LUMICENTER | AA13: LHT44-S4000840 | AB13: 1 | AC13: https://lumicenter.com/produtos/lht44-s | AD13: 0.67 | AE13: 0.85 | AF13: =IF(F13="", "", IFERROR((L13 * F13 * G13) / (AD13 * AE13), "")) -> 10114.135 | AG13: =IF(F13="", "", IFERROR(ROUND(AF13 / (R13 * AB13), 0), "")) -> 3 | AH13: 2 | AI13: 2 | AJ13: =IF(F13="", "", IFERROR(G13 / AI13, "")) -> 2.4 | AK13: =IF(F13="", "", IFERROR(F13 / AH13, "")) -> 2 | AL13: =IF(F13="", "", IFERROR(AJ13 / 2, "")) -> 1.2 | AM13: =IF(F13="", "", IFERROR(AK13 / 2, "")) -> 1 | AN13: =AH13*AI13*AB13*(V13+W13) -> 160 | AO13: =IF(F13="", "", IFERROR(AN13 / X13, "")) -> 161.61616
A14: 9 | B14: Copa | C14: 0.7 | D14: 0.5 | E14: 0.1 | F14: 3.5 | G14: 4.8 | H14: 3 | I14: 0.7 | J14: 0.5 | K14: =IF(F14="", "", H14 - I14 - J14) -> 1.8 | L14: 200 | M14: =IF(F14="", "", 5 * K14 * (F14 + G14) / (F14 * G14)) -> 4.4464286 | N14: =IF(F14="", "", (F14 * G14) / (K14 * (F14 + G14))) -> 1.124498 | O14: Luminária LED | P14: LUMICENTER | Q14: LHT44-S4000840 | R14: 4000 | S14: 80 | T14: 4000 | U14: 50000 | V14: 40 | W14: 0 | X14: 0.99 | Y14: https://lumicenter.com/produtos/lht44-s | Z14: LUMICENTER | AA14: LHT44-S4000840 | AB14: 1 | AC14: https://lumicenter.com/produtos/lht44-s | AD14: 0.65 | AE14: 0.85 | AF14: =IF(F14="", "", IFERROR((L14 * F14 * G14) / (AD14 * AE14), "")) -> 6081.448 | AG14: =IF(F14="", "", IFERROR(ROUND(AF14 / (R14 * AB14), 0), "")) -> 2 | AH14: 1 | AI14: 2 | AJ14: =IF(F14="", "", IFERROR(G14 / AI14, "")) -> 2.4 | AK14: =IF(F14="", "", IFERROR(F14 / AH14, "")) -> 3.5 | AL14: =IF(F14="", "", IFERROR(AJ14 / 2, "")) -> 1.2 | AM14: =IF(F14="", "", IFERROR(AK14 / 2, "")) -> 1.75 | AN14: =AH14*AI14*AB14*(V14+W14) -> 80 | AO14: =IF(F14="", "", IFERROR(AN14 / X14, "")) -> 80.808081
A15: 10 | B15: Ante Sala | C15: 0.7 | D15: 0.5 | E15: 0.1 | F15: 2 | G15: 9 | H15: 3 | I15: 0.7 | J15: 0.5 | K15: =IF(F15="", "", H15 - I15 - J15) -> 1.8 | L15: 200 | M15: =IF(F15="", "", 5 * K15 * (F15 + G15) / (F15 * G15)) -> 5.5 | N15: =IF(F15="", "", (F15 * G15) / (K15 * (F15 + G15))) -> 0.90909091 | O15: Luminária LED | P15: LUMICENTER | Q15: LHT44-S4000840 | R15: 4000 | S15: 80 | T15: 4000 | U15: 50000 | V15: 40 | W15: 0 | X15: 0.99 | Y15: https://lumicenter.com/produtos/lht44-s | Z15: LUMICENTER | AA15: LHT44-S4000840 | AB15: 1 | AC15: https://lumicenter.com/produtos/lht44-s | AD15: 0.58 | AE15: 0.85 | AF15: =IF(F15="", "", IFERROR((L15 * F15 * G15) / (AD15 * AE15), "")) -> 7302.2312 | AG15: =IF(F15="", "", IFERROR(ROUND(AF15 / (R15 * AB15), 0), "")) -> 2 | AH15: 1 | AI15: 3 | AJ15: =IF(F15="", "", IFERROR(G15 / AI15, "")) -> 3 | AK15: =IF(F15="", "", IFERROR(F15 / AH15, "")) -> 2 | AL15: =IF(F15="", "", IFERROR(AJ15 / 2, "")) -> 1.5 | AM15: =IF(F15="", "", IFERROR(AK15 / 2, "")) -> 1 | AN15: =AH15*AI15*AB15*(V15+W15) -> 120 | AO15: =IF(F15="", "", IFERROR(AN15 / X15, "")) -> 121.21212
A16: 11 | B16: BWC1 | C16: 0.7 | D16: 0.5 | E16: 0.1 | F16: 3.57 | G16: 7.2 | H16: 3 | I16: 0.7 | J16: 0.5 | K16: =IF(F16="", "", H16 - I16 - J16) -> 1.8 | L16: 200 | M16: 4 | N16: =IF(F16="", "", (F16 * G16) / (K16 * (F16 + G16))) -> 1.3259053 | O16: Luminária LED | P16: LUMICENTER | Q16: LHT44-S4000840 | R16: 4000 | S16: 80 | T16: 4000 | U16: 50000 | V16: 40 | W16: 0 | X16: 0.99 | Y16: https://lumicenter.com/produtos/lht44-s | Z16: LUMICENTER | AA16: LHT44-S4000840 | AB16: 1 | AC16: https://lumicenter.com/produtos/lht44-s | AD16: 0.68 | AE16: 0.85 | AF16: =IF(F16="", "", IFERROR((L16 * F16 * G16) / (AD16 * AE16), "")) -> 8894.1176 | AG16: =IF(F16="", "", IFERROR(ROUND(AF16 / (R16 * AB16), 0), "")) -> 2 | AH16: 1 | AI16: 2 | AJ16: =IF(F16="", "", IFERROR(G16 / AI16, "")) -> 3.6 | AK16: =IF(F16="", "", IFERROR(F16 / AH16, "")) -> 3.57 | AL16: =IF(F16="", "", IFERROR(AJ16 / 2, "")) -> 1.8 | AM16: =IF(F16="", "", IFERROR(AK16 / 2, "")) -> 1.785 | AN16: =AH16*AI16*AB16*(V16+W16) -> 80 | AO16: =IF(F16="", "", IFERROR(AN16 / X16, "")) -> 80.808081
A17: 12 | B17: BWC2 | C17: 0.7 | D17: 0.5 | E17: 0.1 | F17: 3.57 | G17: 7.2 | H17: 3 | I17: 0.7 | J17: 0.5 | K17: =IF(F17="", "", H17 - I17 - J17) -> 1.8 | L17: 200 | M17: 4 | N17: =IF(F17="", "", (F17 * G17) / (K17 * (F17 + G17))) -> 1.3259053 | O17: Luminária LED | P17: LUMICENTER | Q17: LHT44-S4000840 | R17: 4000 | S17: 80 | T17: 4000 | U17: 50000 | V17: 40 | W17: 0 | X17: 0.99 | Y17: https://lumicenter.com/produtos/lht44-s | Z17: LUMICENTER | AA17: LHT44-S4000840 | AB17: 1 | AC17: https://lumicenter.com/produtos/lht44-s | AD17: 0.68 | AE17: 0.85 | AF17: =IF(F17="", "", IFERROR((L17 * F17 * G17) / (AD17 * AE17), "")) -> 8894.1176 | AG17: =IF(F17="", "", IFERROR(ROUND(AF17 / (R17 * AB17), 0), "")) -> 2 | AH17: 1 | AI17: 2 | AJ17: =IF(F17="", "", IFERROR(G17 / AI17, "")) -> 3.6 | AK17: =IF(F17="", "", IFERROR(F17 / AH17, "")) -> 3.57 | AL17: =IF(F17="", "", IFERROR(AJ17 / 2, "")) -> 1.8 | AM17: =IF(F17="", "", IFERROR(AK17 / 2, "")) -> 1.785 | AN17: =AH17*AI17*AB17*(V17+W17) -> 80 | AO17: =IF(F17="", "", IFERROR(AN17 / X17, "")) -> 80.808081
A18: 13 | B18: BWC3 | C18: 0.7 | D18: 0.5 | E18: 0.1 | F18: 3.5 | G18: 6 | H18: 3 | I18: 0.7 | J18: 0.5 | K18: =IF(F18="", "", H18 - I18 - J18) -> 1.8 | L18: 200 | M18: 4 | N18: =IF(F18="", "", (F18 * G18) / (K18 * (F18 + G18))) -> 1.2280702 | O18: Luminária LED | P18: LUMICENTER | Q18: LHT44-S4000840 | R18: 4000 | S18: 80 | T18: 4000 | U18: 50000 | V18: 40 | W18: 0 | X18: 0.99 | Y18: https://lumicenter.com/produtos/lht44-s | Z18: LUMICENTER | AA18: LHT44-S4000840 | AB18: 1 | AC18: https://lumicenter.com/produtos/lht44-s | AD18: 0.68 | AE18: 0.85 | AF18: =IF(F18="", "", IFERROR((L18 * F18 * G18) / (AD18 * AE18), "")) -> 7266.436 | AG18: =IF(F18="", "", IFERROR(ROUND(AF18 / (R18 * AB18), 0), "")) -> 2 | AH18: 1 | AI18: 2 | AJ18: =IF(F18="", "", IFERROR(G18 / AI18, "")) -> 3 | AK18: =IF(F18="", "", IFERROR(F18 / AH18, "")) -> 3.5 | AL18: =IF(F18="", "", IFERROR(AJ18 / 2, "")) -> 1.5 | AM18: =IF(F18="", "", IFERROR(AK18 / 2, "")) -> 1.75 | AN18: =AH18*AI18*AB18*(V18+W18) -> 80 | AO18: =IF(F18="", "", IFERROR(AN18 / X18, "")) -> 80.808081
A19: 14 | B19: BWC4 | C19: 0.7 | D19: 0.5 | E19: 0.1 | F19: 3.5 | G19: 6 | H19: 3 | I19: 0.7 | J19: 0.5 | K19: =IF(F19="", "", H19 - I19 - J19) -> 1.8 | L19: 200 | M19: 4 | N19: =IF(F19="", "", (F19 * G19) / (K19 * (F19 + G19))) -> 1.2280702 | O19: Luminária LED | P19: LUMICENTER | Q19: LHT44-S4000840 | R19: 4000 | S19: 80 | T19: 4000 | U19: 50000 | V19: 40 | W19: 0 | X19: 0.99 | Y19: https://lumicenter.com/produtos/lht44-s | Z19: LUMICENTER | AA19: LHT44-S4000840 | AB19: 1 | AC19: https://lumicenter.com/produtos/lht44-s | AD19: 0.68 | AE19: 0.85 | AF19: =IF(F19="", "", IFERROR((L19 * F19 * G19) / (AD19 * AE19), "")) -> 7266.436 | AG19: =IF(F19="", "", IFERROR(ROUND(AF19 / (R19 * AB19), 0), "")) -> 2 | AH19: 1 | AI19: 2 | AJ19: =IF(F19="", "", IFERROR(G19 / AI19, "")) -> 3 | AK19: =IF(F19="", "", IFERROR(F19 / AH19, "")) -> 3.5 | AL19: =IF(F19="", "", IFERROR(AJ19 / 2, "")) -> 1.5 | AM19: =IF(F19="", "", IFERROR(AK19 / 2, "")) -> 1.75 | AN19: =AH19*AI19*AB19*(V19+W19) -> 80 | AO19: =IF(F19="", "", IFERROR(AN19 / X19, "")) -> 80.808081
A20: 15 | B20: Vídeo Conferencia | C20: 0.7 | D20: 0.5 | E20: 0.1 | F20: 4.7 | G20: 5.6 | H20: 3 | I20: 0.7 | J20: 0.5 | K20: =IF(F20="", "", H20 - I20 - J20) -> 1.8 | L20: 500 | M20: 4 | N20: =IF(F20="", "", (F20 * G20) / (K20 * (F20 + G20))) -> 1.4196332 | O20: Luminária LED | P20: LUMICENTER | Q20: LHT44-S4000840 | R20: 4000 | S20: 80 | T20: 4000 | U20: 50000 | V20: 40 | W20: 0 | X20: 0.99 | Y20: https://lumicenter.com/produtos/lht44-s | Z20: LUMICENTER | AA20: LHT44-S4000840 | AB20: 1 | AC20: https://lumicenter.com/produtos/lht44-s | AD20: 0.68 | AE20: 0.85 | AF20: =IF(F20="", "", IFERROR((L20 * F20 * G20) / (AD20 * AE20), "")) -> 22768.166 | AG20: =IF(F20="", "", IFERROR(ROUND(AF20 / (R20 * AB20), 0), "")) -> 6 | AH20: 2 | AI20: 3 | AJ20: =IF(F20="", "", IFERROR(G20 / AI20, "")) -> 1.8666667 | AK20: =IF(F20="", "", IFERROR(F20 / AH20, "")) -> 2.35 | AL20: =IF(F20="", "", IFERROR(AJ20 / 2, "")) -> 0.93333333 | AM20: =IF(F20="", "", IFERROR(AK20 / 2, "")) -> 1.175 | AN20: =AH20*AI20*AB20*(V20+W20) -> 240 | AO20: =IF(F20="", "", IFERROR(AN20 / X20, "")) -> 242.42424
A21: 16 | B21: Presidência | C21: 0.7 | D21: 0.5 | E21: 0.1 | F21: 2.7 | G21: 5.6 | H21: 3 | I21: 0.7 | J21: 0.5 | K21: =IF(F21="", "", H21 - I21 - J21) -> 1.8 | L21: 500 | M21: 5 | N21: =IF(F21="", "", (F21 * G21) / (K21 * (F21 + G21))) -> 1.0120482 | O21: Luminária LED | P21: LUMICENTER | Q21: LHT44-S4000840 | R21: 4000 | S21: 80 | T21: 4000 | U21: 50000 | V21: 40 | W21: 0 | X21: 0.99 | Y21: https://lumicenter.com/produtos/lht44-s | Z21: LUMICENTER | AA21: LHT44-S4000840 | AB21: 1 | AC21: https://lumicenter.com/produtos/lht44-s | AD21: 0.61 | AE21: 0.85 | AF21: =IF(F21="", "", IFERROR((L21 * F21 * G21) / (AD21 * AE21), "")) -> 14580.521 | AG21: =IF(F21="", "", IFERROR(ROUND(AF21 / (R21 * AB21), 0), "")) -> 4 | AH21: 1 | AI21: 4 | AJ21: =IF(F21="", "", IFERROR(G21 / AI21, "")) -> 1.4 | AK21: =IF(F21="", "", IFERROR(F21 / AH21, "")) -> 2.7 | AL21: =IF(F21="", "", IFERROR(AJ21 / 2, "")) -> 0.7 | AM21: =IF(F21="", "", IFERROR(AK21 / 2, "")) -> 1.35 | AN21: =AH21*AI21*AB21*(V21+W21) -> 160 | AO21: =IF(F21="", "", IFERROR(AN21 / X21, "")) -> 161.61616
A22: 17 | B22: Diretoria Técnica | C22: 0.7 | D22: 0.5 | E22: 0.1 | F22: 4.5 | G22: 7.7 | H22: 3 | I22: 0.7 | J22: 0.5 | K22: =IF(F22="", "", H22 - I22 - J22) -> 1.8 | L22: 500 | M22: 3 | N22: =IF(F22="", "", (F22 * G22) / (K22 * (F22 + G22))) -> 1.5778689 | O22: Luminária LED | P22: LUMICENTER | Q22: LHT44-S4000840 | R22: 4000 | S22: 80 | T22: 4000 | U22: 50000 | V22: 40 | W22: 0 | X22: 0.99 | Y22: https://lumicenter.com/produtos/lht44-s | Z22: LUMICENTER | AA22: LHT44-S4000840 | AB22: 1 | AC22: https://lumicenter.com/produtos/lht44-s | AD22: 0.77 | AE22: 0.85 | AF22: =IF(F22="", "", IFERROR((L22 * F22 * G22) / (AD22 * AE22), "")) -> 26470.588 | AG22: =IF(F22="", "", IFERROR(ROUND(AF22 / (R22 * AB22), 0), "")) -> 7 | AH22: 2 | AI22: 4 | AJ22: =IF(F22="", "", IFERROR(G22 / AI22, "")) -> 1.925 | AK22: =IF(F22="", "", IFERROR(F22 / AH22, "")) -> 2.25 | AL22: =IF(F22="", "", IFERROR(AJ22 / 2, "")) -> 0.9625 | AM22: =IF(F22="", "", IFERROR(AK22 / 2, "")) -> 1.125 | AN22: =AH22*AI22*AB22*(V22+W22) -> 320 | AO22: =IF(F22="", "", IFERROR(AN22 / X22, "")) -> 323.23232
A23: 18 | B23: Depósito | C23: 0.7 | D23: 0.5 | E23: 0.1 | F23: 3.5 | G23: 7.7 | H23: 3 | I23: 0.7 | J23: 0.5 | K23: =IF(F23="", "", H23 - I23 - J23) -> 1.8 | L23: 100 | M23: 4 | N23: =IF(F23="", "", (F23 * G23) / (K23 * (F23 + G23))) -> 1.3368056 | O23: Luminária LED | P23: LUMICENTER | Q23: LHT44-S4000840 | R23: 4000 | S23: 80 | T23: 4000 | U23: 50000 | V23: 40 | W23: 0 | X23: 0.99 | Y23: https://lumicenter.com/produtos/lht44-s | Z23: LUMICENTER | AA23: LHT44-S4000840 | AB23: 1 | AC23: https://lumicenter.com/produtos/lht44-s | AD23: 0.68 | AE23: 0.85 | AF23: =IF(F23="", "", IFERROR((L23 * F23 * G23) / (AD23 * AE23), "")) -> 4662.6298 | AG23: =IF(F23="", "", IFERROR(ROUND(AF23 / (R23 * AB23), 0), "")) -> 1 | AH23: 1 | AI23: 1 | AJ23: =IF(F23="", "", IFERROR(G23 / AI23, "")) -> 7.7 | AK23: =IF(F23="", "", IFERROR(F23 / AH23, "")) -> 3.5 | AL23: =IF(F23="", "", IFERROR(AJ23 / 2, "")) -> 3.85 | AM23: =IF(F23="", "", IFERROR(AK23 / 2, "")) -> 1.75 | AN23: =AH23*AI23*AB23*(V23+W23) -> 40 | AO23: =IF(F23="", "", IFERROR(AN23 / X23, "")) -> 40.40404
A24: 19 | B24: Circulação 1 | C24: 0.7 | D24: 0.5 | E24: 0.1 | F24: 2 | G24: 7.9 | H24: 3 | I24: 0.7 | J24: 0.5 | K24: =IF(F24="", "", H24 - I24 - J24) -> 1.8 | L24: 100 | M24: 6 | N24: =IF(F24="", "", (F24 * G24) / (K24 * (F24 + G24))) -> 0.88664422 | O24: Luminária LED | P24: LUMICENTER | Q24: LHT44-S4000840 | R24: 4000 | S24: 80 | T24: 4000 | U24: 50000 | V24: 40 | W24: 0 | X24: 0.99 | Y24: https://lumicenter.com/produtos/lht44-s | Z24: LUMICENTER | AA24: LHT44-S4000840 | AB24: 1 | AC24: https://lumicenter.com/produtos/lht44-s | AD24: 0.55 | AE24: 0.85 | AF24: =IF(F24="", "", IFERROR((L24 * F24 * G24) / (AD24 * AE24), "")) -> 3379.6791 | AG24: =IF(F24="", "", IFERROR(ROUND(AF24 / (R24 * AB24), 0), "")) -> 1 | AH24: 1 | AI24: 2 | AJ24: =IF(F24="", "", IFERROR(G24 / AI24, "")) -> 3.95 | AK24: =IF(F24="", "", IFERROR(F24 / AH24, "")) -> 2 | AL24: =IF(F24="", "", IFERROR(AJ24 / 2, "")) -> 1.975 | AM24: =IF(F24="", "", IFERROR(AK24 / 2, "")) -> 1 | AN24: =AH24*AI24*AB24*(V24+W24) -> 80 | AO24: =IF(F24="", "", IFERROR(AN24 / X24, "")) -> 80.808081
A25: 20 | B25: Circulação 2 | C25: 0.7 | D25: 0.5 | E25: 0.1 | F25: 1.3 | G25: 28.4 | H25: 3 | I25: 0.7 | J25: 0.5 | K25: =IF(F25="", "", H25 - I25 - J25) -> 1.8 | L25: 100 | M25: 7 | N25: =IF(F25="", "", (F25 * G25) / (K25 * (F25 + G25))) -> 0.6906098 | O25: Luminária LED | P25: LUMICENTER | Q25: LHT44-S4000840 | R25: 4000 | S25: 80 | T25: 4000 | U25: 50000 | V25: 40 | W25: 0 | X25: 0.99 | Y25: https://lumicenter.com/produtos/lht44-s | Z25: LUMICENTER | AA25: LHT44-S4000840 | AB25: 1 | AC25: https://lumicenter.com/produtos/lht44-s | AD25: 0.5 | AE25: 0.85 | AF25: =IF(F25="", "", IFERROR((L25 * F25 * G25) / (AD25 * AE25), "")) -> 8687.0588 | AG25: =IF(F25="", "", IFERROR(ROUND(AF25 / (R25 * AB25), 0), "")) -> 2 | AH25: 1 | AI25: 5 | AJ25: =IF(F25="", "", IFERROR(G25 / AI25, "")) -> 5.68 | AK25: =IF(F25="", "", IFERROR(F25 / AH25, "")) -> 1.3 | AL25: =IF(F25="", "", IFERROR(AJ25 / 2, "")) -> 2.84 | AM25: =IF(F25="", "", IFERROR(AK25 / 2, "")) -> 0.65 | AN25: =AH25*AI25*AB25*(V25+W25) -> 200 | AO25: =IF(F25="", "", IFERROR(AN25 / X25, "")) -> 202.0202
A26: 21 | B26: Circulação 3 | C26: 0.7 | D26: 0.5 | E26: 0.1 | F26: 1 | G26: 5.1 | H26: 3 | I26: 0.7 | J26: 0.5 | K26: =IF(F26="", "", H26 - I26 - J26) -> 1.8 | L26: 100 | M26: 13 | N26: =IF(F26="", "", (F26 * G26) / (K26 * (F26 + G26))) -> 0.46448087 | O26: Luminária LED | P26: LUMICENTER | Q26: LHT44-S4000840 | R26: 4000 | S26: 80 | T26: 4000 | U26: 50000 | V26: 40 | W26: 0 | X26: 0.99 | Y26: https://lumicenter.com/produtos/lht44-s | Z26: LUMICENTER | AA26: LHT44-S4000840 | AB26: 1 | AC26: https://lumicenter.com/produtos/lht44-s | AD26: 0.28 | AE26: 0.85 | AF26: =IF(F26="", "", IFERROR((L26 * F26 * G26) / (AD26 * AE26), "")) -> 2142.8571 | AG26: =IF(F26="", "", IFERROR(ROUND(AF26 / (R26 * AB26), 0), "")) -> 1 | AH26: 1 | AI26: 2 | AJ26: =IF(F26="", "", IFERROR(G26 / AI26, "")) -> 2.55 | AK26: =IF(F26="", "", IFERROR(F26 / AH26, "")) -> 1 | AL26: =IF(F26="", "", IFERROR(AJ26 / 2, "")) -> 1.275 | AM26: =IF(F26="", "", IFERROR(AK26 / 2, "")) -> 0.5 | AN26: =AH26*AI26*AB26*(V26+W26) -> 80 | AO26: =IF(F26="", "", IFERROR(AN26 / X26, "")) -> 80.808081
A27: 22 | B27: Subestação | C27: 0.7 | D27: 0.5 | E27: 0.1 | F27: 5.6 | G27: 7.7 | H27: 3 | I27: 0.7 | J27: 0.5 | K27: =IF(F27="", "", H27 - I27 - J27) -> 1.8 | L27: 100 | M27: =IF(F27="", "", 5 * K27 * (F27 + G27) / (F27 * G27)) -> 2.775974 | N27: =IF(F27="", "", (F27 * G27) / (K27 * (F27 + G27))) -> 1.8011696 | O27: Luminária LED | P27: LUMICENTER | Q27: LHT44-S4000840 | R27: 4000 | S27: 80 | T27: 4000 | U27: 50000 | V27: 40 | W27: 0 | X27: 0.99 | Y27: https://lumicenter.com/produtos/lht44-s | Z27: LUMICENTER | AA27: LHT44-S4000840 | AB27: 1 | AC27: https://lumicenter.com/produtos/lht44-s | AD27: 0.79 | AE27: 0.85 | AF27: =IF(F27="", "", IFERROR((L27 * F27 * G27) / (AD27 * AE27), "")) -> 6421.4445 | AG27: =IF(F27="", "", IFERROR(ROUND(AF27 / (R27 * AB27), 0), "")) -> 2 | AH27: 1 | AI27: 2 | AJ27: =IF(F27="", "", IFERROR(G27 / AI27, "")) -> 3.85 | AK27: =IF(F27="", "", IFERROR(F27 / AH27, "")) -> 5.6 | AL27: =IF(F27="", "", IFERROR(AJ27 / 2, "")) -> 1.925 | AM27: =IF(F27="", "", IFERROR(AK27 / 2, "")) -> 2.8 | AN27: =AH27*AI27*AB27*(V27+W27) -> 80 | AO27: =IF(F27="", "", IFERROR(AN27 / X27, "")) -> 80.808081

Sheet Previsão de Cargas
A1: PREVISÃO DE CARGAS
A2: Dependência | B2: Dimensões Área [m²] | C2: Dimensões Perímerímetro [m] | D2: Potência de Iluminação [VA] | E2: TUG's Monofásico | G2: TUG's Trifásico | I2: TUE's
E3: Quantidade | F3: Potência [VA] | G3: Quantidade | H3: Potência [VA] | I3: Descrição | J3: Potência [W]
A4: ÁREA FABRIL
A5: =Luminotécnico!B5 -> Tornear e Chanfrar | B5: =Luminotécnico!F5*Luminotécnico!G5 -> 145.8 | C5: =2*(Luminotécnico!F5+Luminotécnico!G5) -> 50.4 | D5: =Luminotécnico!AO5 -> 953.93939 | E5: =ROUNDUP(C5/7.5, 0) -> 7 | F5: =E5*600 -> 4200 | G5: =ROUNDUP(C5/15,0) -> 4 | H5: =G5*6000 -> 24000 | I5: Bancada 1 + Bancada 2 | J5: 4160
A6: =Luminotécnico!B6 -> Polimento | B6: =Luminotécnico!F6*Luminotécnico!G6 -> 132.84 | C6: =2*(Luminotécnico!F6+Luminotécnico!G6) -> 48.8 | D6: =Luminotécnico!AO6 -> 1430.9091 | E6: =ROUNDUP(C6/7.5, 0) -> 7 | F6: =E6*600 -> 4200 | G6: =ROUNDUP(C6/15,0) -> 4 | H6: =G6*6000 -> 24000 | I6: Bancada 3 + Bancada 4 | J6: 4320
A7: =Luminotécnico!B7 -> Colagem e montagem | B7: =Luminotécnico!F7*Luminotécnico!G7 -> 149.4 | C7: =2*(Luminotécnico!F7+Luminotécnico!G7) -> 51.2 | D7: =Luminotécnico!AO7 -> 635.9596 | E7: =ROUNDUP(C7/7.5, 0) -> 7 | F7: =E7*600 -> 4200 | G7: =ROUNDUP(C7/15,0) -> 4 | H7: =G7*6000 -> 24000 | I7: Bancada 5 | J7: 2240
A8: =Luminotécnico!B8 -> Sistemas de Serra | B8: =Luminotécnico!F8*Luminotécnico!G8 -> 136.105 | C8: =2*(Luminotécnico!F8+Luminotécnico!G8) -> 49.7 | D8: =Luminotécnico!AO8 -> 635.9596 | E8: =ROUNDUP(C8/7.5, 0) -> 7 | F8: =E8*600 -> 4200 | G8: =ROUNDUP(C8/15,0) -> 4 | H8: =G8*6000 -> 24000 | I8: Bancada 6 | J8: 5440
A9: =Luminotécnico!B9 -> Inspeção Final | B9: =Luminotécnico!F9*Luminotécnico!G9 -> 96.1675 | C9: =2*(Luminotécnico!F9+Luminotécnico!G9) -> 41.2 | D9: =Luminotécnico!AO9 -> 1669.3939 | E9: =ROUNDUP(C9/7.5, 0) -> 6 | F9: =E9*600 -> 3600 | G9: =ROUNDUP(C9/15,0) -> 3 | H9: =G9*6000 -> 18000
A10: ÁREA COMERCIAL
A11: =Luminotécnico!B11 -> Sala de Estar | B11: =Luminotécnico!F11*Luminotécnico!G11 -> 54.28 | C11: =2*(Luminotécnico!F11+Luminotécnico!G11) -> 30.2 | D11: =IF(B11<=6, 100, 100 + INT((B11 - 6) / 4) * 60) -> 820 | E11: =ROUNDUP(C11/5, 0) -> 7 | F11: =E11*100 -> 700 | G11: 0 | H11: =G11*6000 -> 0 | I11: Ar Condicionado 18.000 BTU/h | J11: 1900
A12: =Luminotécnico!B12 -> Sala de reuniões | B12: =Luminotécnico!F12*Luminotécnico!G12 -> 42.35 | C12: =2*(Luminotécnico!F12+Luminotécnico!G12) -> 26.4 | D12: =IF(B12<=6, 100, 100 + INT((B12 - 6) / 4) * 60) -> 640 | E12: =IF(B12<=37, MAX(ROUNDUP(C12/3,0), ROUNDUP(B12/4,0)), 8+3*ROUNDUP((B12-37)/37,0)) -> 11 | F12: =E12*200 -> 2200 | G12: 0 | H12: =G12*6000 -> 0 | I12: Ar Condicionado 24.000 BTU/h | J12: 2500
A13: =Luminotécnico!B13 -> Recepção | B13: =Luminotécnico!F13*Luminotécnico!G13 -> 19.2 | C13: =2*(Luminotécnico!F13+Luminotécnico!G13) -> 17.6 | D13: =IF(B13<=6, 100, 100 + INT((B13 - 6) / 4) * 60) -> 280 | E13: =IF(B13<=37, MAX(ROUNDUP(C13/3,0), ROUNDUP(B13/4,0)), 8+3*ROUNDUP((B13-37)/37,0)) -> 6 | F13: =E13*200 -> 1200 | G13: 0 | H13: =G13*6000 -> 0 | I13: Ar Condicionado 12.000 BTU/h | J13: 1400
A14: =Luminotécnico!B14 -> Copa | B14: =Luminotécnico!F14*Luminotécnico!G14 -> 16.8 | C14: =2*(Luminotécnico!F14+Luminotécnico!G14) -> 16.6 | D14: =IF(B14<=6, 100, 100 + INT((B14 - 6) / 4) * 60) -> 220 | E14: =ROUNDUP(C14/3.5, 0) -> 5 | F14: =IF(E14>3, 3*600 + (E14-3)*100, E14*600) -> 2000 | G14: 0 | H14: =G14*6000 -> 0
A15: =Luminotécnico!B15 -> Ante Sala | B15: =Luminotécnico!F15*Luminotécnico!G15 -> 18 | C15: =2*(Luminotécnico!F15+Luminotécnico!G15) -> 22 | D15: =IF(B15<=6, 100, 100 + INT((B15 - 6) / 4) * 60) -> 280 | E15: =ROUNDUP(C15/5, 0) -> 5 | F15: =E15*100 -> 500 | G15: 0 | H15: =G15*6000 -> 0
A16: =Luminotécnico!B16 -> BWC1 | B16: =Luminotécnico!F16*Luminotécnico!G16 -> 25.704 | C16: =2*(Luminotécnico!F16+Luminotécnico!G16) -> 21.54 | D16: =IF(B16<=6, 100, 100 + INT((B16 - 6) / 4) * 60) -> 340 | E16: 1 | F16: 600 | G16: 0 | H16: =G16*6000 -> 0 | I16: Secador de Mãos | J16: 1500
A17: =Luminotécnico!B17 -> BWC2 | B17: =Luminotécnico!F17*Luminotécnico!G17 -> 25.704 | C17: =2*(Luminotécnico!F17+Luminotécnico!G17) -> 21.54 | D17: =IF(B17<=6, 100, 100 + INT((B17 - 6) / 4) * 60) -> 340 | E17: 1 | F17: 600 | G17: 0 | H17: =G17*6000 -> 0 | I17: Secador de Mãos | J17: 1500
A18: =Luminotécnico!B18 -> BWC3 | B18: =Luminotécnico!F18*Luminotécnico!G18 -> 21 | C18: =2*(Luminotécnico!F18+Luminotécnico!G18) -> 19 | D18: =IF(B18<=6, 100, 100 + INT((B18 - 6) / 4) * 60) -> 280 | E18: 1 | F18: 600 | G18: 0 | H18: =G18*6000 -> 0 | I18: Secador de Mãos | J18: 1500
A19: =Luminotécnico!B19 -> BWC4 | B19: =Luminotécnico!F19*Luminotécnico!G19 -> 21 | C19: =2*(Luminotécnico!F19+Luminotécnico!G19) -> 19 | D19: =IF(B19<=6, 100, 100 + INT((B19 - 6) / 4) * 60) -> 280 | E19: 1 | F19: 600 | G19: 0 | H19: =G19*6000 -> 0 | I19: Secador de Mãos | J19: 1500
A20: =Luminotécnico!B20 -> Vídeo Conferencia | B20: =Luminotécnico!F20*Luminotécnico!G20 -> 26.32 | C20: =2*(Luminotécnico!F20+Luminotécnico!G20) -> 20.6 | D20: =IF(B20<=6, 100, 100 + INT((B20 - 6) / 4) * 60) -> 400 | E20: =IF(B20<=37, MAX(ROUNDUP(C20/3,0), ROUNDUP(B20/4,0)), 8+3*ROUNDUP((B20-37)/37,0)) -> 7 | F20: =E20*200 -> 1400 | G20: 0 | H20: =G20*6000 -> 0 | I20: Ar Condicionado 18.000 BTU/h | J20: 1900
A21: =Luminotécnico!B21 -> Presidência | B21: =Luminotécnico!F21*Luminotécnico!G21 -> 15.12 | C21: =2*(Luminotécnico!F21+Luminotécnico!G21) -> 16.6 | D21: =IF(B21<=6, 100, 100 + INT((B21 - 6) / 4) * 60) -> 220 | E21: =IF(B21<=37, MAX(ROUNDUP(C21/3,0), ROUNDUP(B21/4,0)), 8+3*ROUNDUP((B21-37)/37,0)) -> 6 | F21: =E21*200 -> 1200 | G21: 0 | H21: =G21*6000 -> 0 | I21: Ar Condicionado 12.000 BTU/h | J21: 1400
A22: =Luminotécnico!B22 -> Diretoria Técnica | B22: =Luminotécnico!F22*Luminotécnico!G22 -> 34.65 | C22: =2*(Luminotécnico!F22+Luminotécnico!G22) -> 24.4 | D22: =IF(B22<=6, 100, 100 + INT((B22 - 6) / 4) * 60) -> 520 | E22: =IF(B22<=37, MAX(ROUNDUP(C22/3,0), ROUNDUP(B22/4,0)), 8+3*ROUNDUP((B22-37)/37,0)) -> 9 | F22: =E22*200 -> 1800 | G22: 0 | H22: =G22*6000 -> 0 | I22: Ar Condicionado 12.000 BTU/h | J22: 1400
A23: =Luminotécnico!B23 -> Depósito | B23: =Luminotécnico!F23*Luminotécnico!G23 -> 26.95 | C23: =2*(Luminotécnico!F23+Luminotécnico!G23) -> 22.4 | D23: =IF(B23<=6, 100, 100 + INT((B23 - 6) / 4) * 60) -> 400 | E23: =ROUNDUP(C23/5, 0) -> 5 | F23: =E23*100 -> 500 | G23: 0 | H23: =G23*6000 -> 0 | I23: Carregador de Baterias (TUE) | J23: 6000
A24: =Luminotécnico!B24 -> Circulação 1 | B24: =Luminotécnico!F24*Luminotécnico!G24 -> 15.8 | C24: =2*(Luminotécnico!F24+Luminotécnico!G24) -> 19.8 | D24: =IF(B24<=6, 100, 100 + INT((B24 - 6) / 4) * 60) -> 220 | E24: =ROUNDUP(C24/5, 0) -> 4 | F24: =E24*100 -> 400 | G24: 0 | H24: =G24*6000 -> 0
A25: =Luminotécnico!B25 -> Circulação 2 | B25: =Luminotécnico!F25*Luminotécnico!G25 -> 36.92 | C25: =2*(Luminotécnico!F25+Luminotécnico!G25) -> 59.4 | D25: =IF(B25<=6, 100, 100 + INT((B25 - 6) / 4) * 60) -> 520 | E25: =ROUNDUP(C25/5, 0) -> 12 | F25: =E25*100 -> 1200 | G25: 0 | H25: =G25*6000 -> 0
A26: =Luminotécnico!B26 -> Circulação 3 | B26: =Luminotécnico!F26*Luminotécnico!G26 -> 5.1 | C26: =2*(Luminotécnico!F26+Luminotécnico!G26) -> 12.2 | D26: =IF(B26<=6, 100, 100 + INT((B26 - 6) / 4) * 60) -> 100 | E26: 2 | F26: =E26*100 -> 200 | G26: 0 | H26: =G26*6000 -> 0
A27: =Luminotécnico!B27 -> Subestação | B27: =Luminotécnico!F27*Luminotécnico!G27 -> 43.12 | C27: =2*(Luminotécnico!F27+Luminotécnico!G27) -> 26.6 | D27: =IF(B27<=6, 100, 100 + INT((B27 - 6) / 4) * 60) -> 640 | E27: =ROUNDUP(C27/5, 0) -> 6 | F27: =E27*100 -> 600 | G27: 0 | H27: =G27*6000 -> 0 | I27: Exaustor / TUE | J27: 6000

Sheet Divisão dos Circuitos
A1: DIVISÃO DOS CIRCUITOS
A2: Circuito N° - Tipo | B2: VN - Tensão [V] | C2: Origem | D2: Destino | E2: S1 - Seção Mínima [mm²] | F2: Tipo de Fornecimento | G2: F.P. | H2: Potências | K2: IN -Corrente de projeto [A] | L2: Proteção Disjuntor Termomagnético - DTM | N2: Proteção Interruptor Diferencial Residual - IDR
H3: P Ativa [W] | I3: S Aparente [VA] | J3: Q Reativa [VAr] | L3: n° de polos | M3: ID - Corrente nominal [A] | N3: n° de polos | O3: Corrente nominal [A]
A4: QD1 - QUADRO DE DISTRIBUIÇÃO 1
A5: 01 - Iluminação | B5: 220 | C5: QD1 | D5: Tornear e Chanfrar, Polimento | E5: 1.5 | F5: 1 | G5: 0.99 | H5: =I5*G5 -> 2361 | I5: ='Previsão de Cargas'!D5+'Previsão de Cargas'!D6 -> 2384.8485 | J5: =SQRT(I5^2-H5^2) -> 336.42428 | K5: =IF(F5=3, I5/(SQRT(3)*B5), I5/(F5*B5)) -> 10.84022 | L5: 1 | M5: 16 | N5: 2 | O5: 25
A6: 12 - TUGs | B6: 220 | C6: QD1 | D6: Tornear e Chanfrar - Circuito 1 | E6: 2.5 | F6: 1 | G6: 0.8 | H6: =I6*G6 -> 1920 | I6: =ROUNDUP('Previsão de Cargas'!E5/2,0)*600 -> 2400 | J6: =SQRT(I6^2-H6^2) -> 1440 | K6: =IF(F6=3, I6/(SQRT(3)*B6), I6/(F6*B6)) -> 10.909091 | L6: 1 | M6: 16 | N6: 2 | O6: 25
A7: 13 - TUGs | B7: 220 | C7: QD1 | D7: Tornear e Chanfrar - Circuito 2 | E7: 2.5 | F7: 1 | G7: 0.8 | H7: =I7*G7 -> 1440 | I7: =('Previsão de Cargas'!E5-ROUNDUP('Previsão de Cargas'!E5/2,0))*600 -> 1800 | J7: =SQRT(I7^2-H7^2) -> 1080 | K7: =IF(F7=3, I7/(SQRT(3)*B7), I7/(F7*B7)) -> 8.1818182 | L7: 1 | M7: 10 | N7: 2 | O7: 25
A8: 14 - TUGs | B8: 220 | C8: QD1 | D8: Polimento - Circuito 1 | E8: 2.5 | F8: 1 | G8: 0.8 | H8: =I8*G8 -> 1920 | I8: =ROUNDUP('Previsão de Cargas'!E6/2,0)*600 -> 2400 | J8: =SQRT(I8^2-H8^2) -> 1440 | K8: =IF(F8=3, I8/(SQRT(3)*B8), I8/(F8*B8)) -> 10.909091 | L8: 1 | M8: 16 | N8: 2 | O8: 25
A9: 15 - TUGs | B9: 220 | C9: QD1 | D9: Polimento - Circuito 2 | E9: 2.5 | F9: 1 | G9: 0.8 | H9: =I9*G9 -> 1440 | I9: =('Previsão de Cargas'!E6-ROUNDUP('Previsão de Cargas'!E6/2,0))*600 -> 1800 | J9: =SQRT(I9^2-H9^2) -> 1080 | K9: =IF(F9=3, I9/(SQRT(3)*B9), I9/(F9*B9)) -> 8.1818182 | L9: 1 | M9: 10 | N9: 2 | O9: 25
A10: 22 - TUGs Trifásicas | B10: 380 | C10: QD1 | D10: Tornear e Chanfrar - Circuito 1 | E10: 2.5 | F10: 3 | G10: 0.8 | H10: =I10*G10 -> 9600 | I10: 12000 | J10: =SQRT(I10^2-H10^2) -> 7200 | K10: =IF(F10=3, I10/(SQRT(3)*B10), I10/(F10*B10)) -> 18.232114 | L10: 3 | M10: 20 | N10: 4 | O10: 25
A11: 23 - TUGs Trifásicas | B11: 380 | C11: QD1 | D11: Polimento - Circuito 1 | E11: 2.5 | F11: 3 | G11: 0.8 | H11: =I11*G11 -> 9600 | I11: 12000 | J11: =SQRT(I11^2-H11^2) -> 7200 | K11: =IF(F11=3, I11/(SQRT(3)*B11), I11/(F11*B11)) -> 18.232114 | L11: 3 | M11: 20 | N11: 4 | O11: 25
A12: 38 - TUGs Trifásicas | B12: 380 | C12: QD1 | D12: Tornear e Chanfrar - Circuito 2 | E12: 2.5 | F12: 3 | G12: 0.8 | H12: =I12*G12 -> 9600 | I12: 12000 | J12: =SQRT(I12^2-H12^2) -> 7200 | K12: =IF(F12=3, I12/(SQRT(3)*B12), I12/(F12*B12)) -> 18.232114 | L12: 3 | M12: 20 | N12: 4 | O12: 25
A13: 39 - TUGs Trifásicas | B13: 380 | C13: QD1 | D13: Polimento - Circuito 2 | E13: 2.5 | F13: 3 | G13: 0.8 | H13: =I13*G13 -> 9600 | I13: 12000 | J13: =SQRT(I13^2-H13^2) -> 7200 | K13: =IF(F13=3, I13/(SQRT(3)*B13), I13/(F13*B13)) -> 18.232114 | L13: 3 | M13: 20 | N13: 4 | O13: 25
A14: 44 - TUE Bancada 1 | B14: 220 | C14: QD1 | D14: Bancada 1 | E14: 2.5 | F14: 1 | G14: 0.8 | H14: =I14*G14 -> 2400 | I14: 3000 | J14: =SQRT(I14^2-H14^2) -> 1800 | K14: =IF(F14=3, I14/(SQRT(3)*B14), I14/(F14*B14)) -> 13.636364 | L14: 1 | M14: 16 | N14: 2 | O14: 25
A15: 45 - TUE Bancada 2 | B15: 220 | C15: QD1 | D15: Bancada 2 | E15: 2.5 | F15: 1 | G15: 0.8 | H15: =I15*G15 -> 1760 | I15: 2200 | J15: =SQRT(I15^2-H15^2) -> 1320 | K15: =IF(F15=3, I15/(SQRT(3)*B15), I15/(F15*B15)) -> 10 | L15: 1 | M15: 16 | N15: 2 | O15: 25
A16: 46 - TUE Bancada 3 | B16: 220 | C16: QD1 | D16: Bancada 3 | E16: 2.5 | F16: 1 | G16: 0.8 | H16: =I16*G16 -> 1600 | I16: 2000 | J16: =SQRT(I16^2-H16^2) -> 1200 | K16: =IF(F16=3, I16/(SQRT(3)*B16), I16/(F16*B16)) -> 9.0909091 | L16: 1 | M16: 10 | N16: 2 | O16: 25
A17: 47 - TUE Bancada 4 | B17: 220 | C17: QD1 | D17: Bancada 4 | E17: 2.5 | F17: 1 | G17: 0.8 | H17: =I17*G17 -> 2720 | I17: 3400 | J17: =SQRT(I17^2-H17^2) -> 2040 | K17: =IF(F17=3, I17/(SQRT(3)*B17), I17/(F17*B17)) -> 15.454545 | L17: 1 | M17: 16 | N17: 2 | O17: 25
A18: QD2 - QUADRO DE DISTRIBUIÇÃO 2
A19: 02 - Iluminação | B19: 220 | C19: QD2 | D19: Colagem e Montagem, Sistemas de Serra, BWC 1 e 2 | E19: 1.5 | F19: 1 | G19: 0.99 | H19: =I19*G19 -> 1932.4 | I19: ='Previsão de Cargas'!D7+'Previsão de Cargas'!D8+'Previsão de Cargas'!D16+'Previsão de Cargas'!D17 -> 1951.9192 | J19: =SQRT(I19^2-H19^2) -> 275.35209 | K19: =IF(F19=3, I19/(SQRT(3)*B19), I19/(F19*B19)) -> 8.87236 | L19: 1 | M19: 10 | N19: 2 | O19: 25
A20: 05 - Iluminação | B20: 220 | C20: QD2 | D20: Inspeção Final | E20: 1.5 | F20: 1 | G20: 0.99 | H20: =I20*G20 -> 1652.7 | I20: ='Previsão de Cargas'!D9 -> 1669.3939 | J20: =SQRT(I20^2-H20^2) -> 235.497 | K20: =IF(F20=3, I20/(SQRT(3)*B20), I20/(F20*B20)) -> 7.5881543 | L20: 1 | M20: 10 | N20: 2 | O20: 25
A21: 07 - TUGs | B21: 220 | C21: QD2 | D21: Sanitários Operacionais (BWC 1 e 2) | E21: 2.5 | F21: 1 | G21: 0.8 | H21: =I21*G21 -> 960 | I21: ='Previsão de Cargas'!F16+'Previsão de Cargas'!F17 -> 1200 | J21: =SQRT(I21^2-H21^2) -> 720 | K21: =IF(F21=3, I21/(SQRT(3)*B21), I21/(F21*B21)) -> 5.4545455 | L21: 1 | M21: 10 | N21: 2 | O21: 25
A22: 16 - TUGs | B22: 220 | C22: QD2 | D22: Colagem e Montagem - Circuito 1 | E22: 2.5 | F22: 1 | G22: 0.8 | H22: =I22*G22 -> 1920 | I22: =ROUNDUP('Previsão de Cargas'!E7/2,0)*600 -> 2400 | J22: =SQRT(I22^2-H22^2) -> 1440 | K22: =IF(F22=3, I22/(SQRT(3)*B22), I22/(F22*B22)) -> 10.909091 | L22: 1 | M22: 16 | N22: 2 | O22: 25
A23: 17 - TUGs | B23: 220 | C23: QD2 | D23: Colagem e Montagem - Circuito 2 | E23: 2.5 | F23: 1 | G23: 0.8 | H23: =I23*G23 -> 1440 | I23: =('Previsão de Cargas'!E7-ROUNDUP('Previsão de Cargas'!E7/2,0))*600 -> 1800 | J23: =SQRT(I23^2-H23^2) -> 1080 | K23: =IF(F23=3, I23/(SQRT(3)*B23), I23/(F23*B23)) -> 8.1818182 | L23: 1 | M23: 10 | N23: 2 | O23: 25
A24: 18 - TUGs | B24: 220 | C24: QD2 | D24: Sistemas de Serra - Circuito 1 | E24: 2.5 | F24: 1 | G24: 0.8 | H24: =I24*G24 -> 1920 | I24: =ROUNDUP('Previsão de Cargas'!E8/2,0)*600 -> 2400 | J24: =SQRT(I24^2-H24^2) -> 1440 | K24: =IF(F24=3, I24/(SQRT(3)*B24), I24/(F24*B24)) -> 10.909091 | L24: 1 | M24: 16 | N24: 2 | O24: 25
A25: 19 - TUGs | B25: 220 | C25: QD2 | D25: Sistemas de Serra - Circuito 2 | E25: 2.5 | F25: 1 | G25: 0.8 | H25: =I25*G25 -> 1440 | I25: =('Previsão de Cargas'!E8-ROUNDUP('Previsão de Cargas'!E8/2,0))*600 -> 1800 | J25: =SQRT(I25^2-H25^2) -> 1080 | K25: =IF(F25=3, I25/(SQRT(3)*B25), I25/(F25*B25)) -> 8.1818182 | L25: 1 | M25: 10 | N25: 2 | O25: 25
A26: 20 - TUGs | B26: 220 | C26: QD2 | D26: Inspeção Final - Circuito 1 | E26: 2.5 | F26: 1 | G26: 0.8 | H26: =I26*G26 -> 1440 | I26: =ROUNDUP('Previsão de Cargas'!E9/2,0)*600 -> 1800 | J26: =SQRT(I26^2-H26^2) -> 1080 | K26: =IF(F26=3, I26/(SQRT(3)*B26), I26/(F26*B26)) -> 8.1818182 | L26: 1 | M26: 10 | N26: 2 | O26: 25
A27: 21 - TUGs | B27: 220 | C27: QD2 | D27: Inspeção Final - Circuito 2 | E27: 2.5 | F27: 1 | G27: 0.8 | H27: =I27*G27 -> 1440 | I27: =('Previsão de Cargas'!E9-ROUNDUP('Previsão de Cargas'!E9/2,0))*600 -> 1800 | J27: =SQRT(I27^2-H27^2) -> 1080 | K27: =IF(F27=3, I27/(SQRT(3)*B27), I27/(F27*B27)) -> 8.1818182 | L27: 1 | M27: 10 | N27: 2 | O27: 25
A28: 24 - TUGs Trifásicas | B28: 380 | C28: QD2 | D28: Colagem e Montagem - Circuito 1 | E28: 2.5 | F28: 3 | G28: 0.8 | H28: =I28*G28 -> 9600 | I28: ='Previsão de Cargas'!H7/2 -> 12000 | J28: =SQRT(I28^2-H28^2) -> 7200 | K28: =IF(F28=3, I28/(SQRT(3)*B28), I28/(F28*B28)) -> 18.232114 | L28: 3 | M28: 20 | N28: 4 | O28: 25
A29: 25 - TUGs Trifásicas | B29: 380 | C29: QD2 | D29: Colagem e Montagem - Circuito 2 | E29: 2.5 | F29: 3 | G29: 0.8 | H29: =I29*G29 -> 9600 | I29: ='Previsão de Cargas'!H7/2 -> 12000 | J29: =SQRT(I29^2-H29^2) -> 7200 | K29: =IF(F29=3, I29/(SQRT(3)*B29), I29/(F29*B29)) -> 18.232114 | L29: 3 | M29: 20 | N29: 4 | O29: 25
A30: 26 - TUGs Trifásicas | B30: 380 | C30: QD2 | D30: Sistemas de Serra - Circuito 1 | E30: 2.5 | F30: 3 | G30: 0.8 | H30: =I30*G30 -> 9600 | I30: 12000 | J30: =SQRT(I30^2-H30^2) -> 7200 | K30: =IF(F30=3, I30/(SQRT(3)*B30), I30/(F30*B30)) -> 18.232114 | L30: 3 | M30: 20 | N30: 4 | O30: 25
A31: 27 - TUGs Trifásicas | B31: 380 | C31: QD2 | D31: Inspeção Final | E31: 2.5 | F31: 3 | G31: 0.8 | H31: =I31*G31 -> 14400 | I31: ='Previsão de Cargas'!H9 -> 18000 | J31: =SQRT(I31^2-H31^2) -> 10800 | K31: =IF(F31=3, I31/(SQRT(3)*B31), I31/(F31*B31)) -> 27.348171 | L31: 3 | M31: 32 | N31: 4 | O31: 40
A32: 30 - TUE | B32: 220 | C32: QD2 | D32: Secadores de Mãos - BWC 1 e 2 | E32: 2.5 | F32: 1 | G32: 0.98 | H32: =I32*G32 -> 3000 | I32: =('Previsão de Cargas'!J16+'Previsão de Cargas'!J17)/G32 -> 3061.2245 | J32: =SQRT(I32^2-H32^2) -> 609.17598 | K32: =IF(F32=3, I32/(SQRT(3)*B32), I32/(F32*B32)) -> 13.914657 | L32: 1 | M32: 16 | N32: 2 | O32: 25
A33: 40 - TUGs Trifásicas | B33: 380 | C33: QD2 | D33: Sistemas de Serra - Circuito 2 | E33: 2.5 | F33: 3 | G33: 0.8 | H33: =I33*G33 -> 9600 | I33: 12000 | J33: =SQRT(I33^2-H33^2) -> 7200 | K33: =IF(F33=3, I33/(SQRT(3)*B33), I33/(F33*B33)) -> 18.232114 | L33: 3 | M33: 20 | N33: 4 | O33: 25
A34: 48 - TUE Bancada 5 | B34: 220 | C34: QD2 | D34: Bancada 5 | E34: 2.5 | F34: 1 | G34: 0.8 | H34: =I34*G34 -> 2240 | I34: 2800 | J34: =SQRT(I34^2-H34^2) -> 1680 | K34: =IF(F34=3, I34/(SQRT(3)*B34), I34/(F34*B34)) -> 12.727273 | L34: 1 | M34: 16 | N34: 2 | O34: 25
A35: 49 - TUE Bancada 6 | B35: 380 | C35: QD2 | D35: Bancada 6 | E35: 2.5 | F35: 2 | G35: 0.8 | H35: =I35*G35 -> 5440 | I35: 6800 | J35: =SQRT(I35^2-H35^2) -> 4080 | K35: =I35/380 -> 17.894737 | L35: 2 | M35: 20 | N35: 2 | O35: 25
A36: QD3 - QUADRO DE DISTRIBUIÇÃO 3
A37: 03 - Iluminação | B37: 220 | C37: QD3 | D37: Sala de Estar, Reuniões, Recepção, Copa | E37: 1.5 | F37: 1 | G37: 0.99 | H37: =I37*G37 -> 1940.4 | I37: ='Previsão de Cargas'!D11+'Previsão de Cargas'!D12+'Previsão de Cargas'!D13+'Previsão de Cargas'!D14 -> 1960 | J37: =SQRT(I37^2-H37^2) -> 276.49203 | K37: =IF(F37=3, I37/(SQRT(3)*B37), I37/(F37*B37)) -> 8.9090909 | L37: 1 | M37: 10 | N37: 2 | O37: 25
A38: 06 - TUGs | B38: 220 | C38: QD3 | D38: Copa | E38: 2.5 | F38: 1 | G38: 0.8 | H38: =I38*G38 -> 1600 | I38: ='Previsão de Cargas'!F14 -> 2000 | J38: =SQRT(I38^2-H38^2) -> 1200 | K38: =IF(F38=3, I38/(SQRT(3)*B38), I38/(F38*B38)) -> 9.0909091 | L38: 1 | M38: 10 | N38: 2 | O38: 25
A39: 08 - TUGs | B39: 220 | C39: QD3 | D39: Sanitários Administrativos (BWC 3 e 4) | E39: 2.5 | F39: 1 | G39: 0.8 | H39: =I39*G39 -> 960 | I39: ='Previsão de Cargas'!F18+'Previsão de Cargas'!F19 -> 1200 | J39: =SQRT(I39^2-H39^2) -> 720 | K39: =IF(F39=3, I39/(SQRT(3)*B39), I39/(F39*B39)) -> 5.4545455 | L39: 1 | M39: 10 | N39: 2 | O39: 25
A40: 10 - TUGs | B40: 220 | C40: QD3 | D40: Sala de Estar, Sala de Reuniões | E40: 2.5 | F40: 1 | G40: 0.8 | H40: =I40*G40 -> 2320 | I40: ='Previsão de Cargas'!F11+'Previsão de Cargas'!F12 -> 2900 | J40: =SQRT(I40^2-H40^2) -> 1740 | K40: =IF(F40=3, I40/(SQRT(3)*B40), I40/(F40*B40)) -> 13.181818 | L40: 1 | M40: 16 | N40: 2 | O40: 25
...

Sheet Capac.Cond.Corre.
A1: CRITÉRIO DA CAPACIDADE DE CONDUÇÃO DE CORRENTE
A3: Circuito N° - Tipo | B3: Origem | C3: Destino | D3: IN [A] | E3: FT (F.Temp.) | F3: N° Circ. Agrup. | G3: FA (F.Agrup.) | H3: IN' [A] | I3: Método Instala. | J3: Tipo de Isolação | K3: N° Cond. Carregados | L3: S2 - Seção (mm²)
A4: QD1 - QUADRO DE DISTRIBUIÇÃO 1
A5: 01 - Iluminação | B5: QD1 | C5: Tornear e Chanfrar, Polimento | D5: ='Divisão dos Circuitos'!K5 -> 10.84022 | E5: 1 | F5: 1 | G5: 1 | H5: =D5/(E5*G5) -> 10.84022 | I5: B2 | J5: PVC | K5: 2 | L5: 1.5
A6: 12 - TUGs | B6: QD1 | C6: Tornear e Chanfrar - Circuito 1 | D6: ='Divisão dos Circuitos'!K6 -> 10.909091 | E6: 1 | F6: 1 | G6: 1 | H6: =D6/(E6*G6) -> 10.909091 | I6: B2 | J6: PVC | K6: 2 | L6: 2.5
A7: 13 - TUGs | B7: QD1 | C7: Tornear e Chanfrar - Circuito 2 | D7: ='Divisão dos Circuitos'!K7 -> 8.1818182 | E7: 1 | F7: 1 | G7: 1 | H7: =D7/(E7*G7) -> 8.1818182 | I7: B2 | J7: PVC | K7: 2 | L7: 2.5
A8: 14 - TUGs | B8: QD1 | C8: Polimento - Circuito 1 | D8: ='Divisão dos Circuitos'!K8 -> 10.909091 | E8: 1 | F8: 1 | G8: 1 | H8: =D8/(E8*G8) -> 10.909091 | I8: B2 | J8: PVC | K8: 2 | L8: 2.5
A9: 15 - TUGs | B9: QD1 | C9: Polimento - Circuito 2 | D9: ='Divisão dos Circuitos'!K9 -> 8.1818182 | E9: 1 | F9: 1 | G9: 1 | H9: =D9/(E9*G9) -> 8.1818182 | I9: B2 | J9: PVC | K9: 2 | L9: 2.5
A10: 22 - TUGs Trifásicas | B10: QD1 | C10: Tornear e Chanfrar - Circuito 1 | D10: ='Divisão dos Circuitos'!K10 -> 18.232114 | E10: 1 | F10: 1 | G10: 1 | H10: =D10/(E10*G10) -> 18.232114 | I10: B2 | J10: PVC | K10: 3 | L10: 2.5
A11: 23 - TUGs Trifásicas | B11: QD1 | C11: Polimento - Circuito 1 | D11: ='Divisão dos Circuitos'!K11 -> 18.232114 | E11: 1 | F11: 1 | G11: 1 | H11: =D11/(E11*G11) -> 18.232114 | I11: B2 | J11: PVC | K11: 3 | L11: 2.5
A12: 38 - TUGs Trifásicas | B12: QD1 | C12: Tornear e Chanfrar - Circuito 2 | D12: ='Divisão dos Circuitos'!K12 -> 18.232114 | E12: 1 | F12: 1 | G12: 1 | H12: =D12/(E12*G12) -> 18.232114 | I12: B2 | J12: PVC | K12: 3 | L12: 2.5
A13: 39 - TUGs Trifásicas | B13: QD1 | C13: Polimento - Circuito 2 | D13: ='Divisão dos Circuitos'!K13 -> 18.232114 | E13: 1 | F13: 1 | G13: 1 | H13: =D13/(E13*G13) -> 18.232114 | I13: B2 | J13: PVC | K13: 3 | L13: 2.5
A14: 44 - TUE Bancada 1 | B14: QD1 | C14: Bancada 1 | D14: ='Divisão dos Circuitos'!K14 -> 13.636364 | E14: 1 | F14: 1 | G14: 1 | H14: =D14/(E14*G14) -> 13.636364 | I14: B2 | J14: PVC | K14: 2 | L14: 2.5
A15: 45 - TUE Bancada 2 | B15: QD1 | C15: Bancada 2 | D15: ='Divisão dos Circuitos'!K15 -> 10 | E15: 1 | F15: 1 | G15: 1 | H15: =D15/(E15*G15) -> 10 | I15: B2 | J15: PVC | K15: 2 | L15: 2.5
A16: 46 - TUE Bancada 3 | B16: QD1 | C16: Bancada 3 | D16: ='Divisão dos Circuitos'!K16 -> 9.0909091 | E16: 1 | F16: 1 | G16: 1 | H16: =D16/(E16*G16) -> 9.0909091 | I16: B2 | J16: PVC | K16: 2 | L16: 2.5
A17: 47 - TUE Bancada 4 | B17: QD1 | C17: Bancada 4 | D17: ='Divisão dos Circuitos'!K17 -> 15.454545 | E17: 1 | F17: 1 | G17: 1 | H17: =D17/(E17*G17) -> 15.454545 | I17: B2 | J17: PVC | K17: 2 | L17: 2.5
A18: QD2 - QUADRO DE DISTRIBUIÇÃO 2
A19: 02 - Iluminação | B19: QD2 | C19: Colagem e Montagem, Sistemas de Serra, BWC 1 e 2 | D19: ='Divisão dos Circuitos'!K19 -> 8.87236 | E19: 1 | F19: 3 | G19: 0.7 | H19: =D19/(E19*G19) -> 12.6748 | I19: B2 | J19: PVC | K19: 2 | L19: 1.5
A20: 05 - Iluminação | B20: QD2 | C20: Inspeção Final | D20: ='Divisão dos Circuitos'!K20 -> 7.5881543 | E20: 1 | F20: 1 | G20: 1 | H20: =D20/(E20*G20) -> 7.5881543 | I20: B2 | J20: PVC | K20: 2 | L20: 1.5
A21: 07 - TUGs | B21: QD2 | C21: Sanitários Operacionais (BWC 1 e 2) | D21: ='Divisão dos Circuitos'!K21 -> 5.4545455 | E21: 1 | F21: 3 | G21: 0.7 | H21: =D21/(E21*G21) -> 7.7922078 | I21: B1 | J21: PVC | K21: 2 | L21: 2.5
A22: 16 - TUGs | B22: QD2 | C22: Colagem e Montagem - Circuito 1 | D22: ='Divisão dos Circuitos'!K22 -> 10.909091 | E22: 1 | F22: 1 | G22: 1 | H22: =D22/(E22*G22) -> 10.909091 | I22: B2 | J22: PVC | K22: 2 | L22: 2.5
A23: 17 - TUGs | B23: QD2 | C23: Colagem e Montagem - Circuito 2 | D23: ='Divisão dos Circuitos'!K23 -> 8.1818182 | E23: 1 | F23: 1 | G23: 1 | H23: =D23/(E23*G23) -> 8.1818182 | I23: B2 | J23: PVC | K23: 2 | L23: 2.5
A24: 18 - TUGs | B24: QD2 | C24: Sistemas de Serra - Circuito 1 | D24: ='Divisão dos Circuitos'!K24 -> 10.909091 | E24: 1 | F24: 1 | G24: 1 | H24: =D24/(E24*G24) -> 10.909091 | I24: B2 | J24: PVC | K24: 2 | L24: 2.5
A25: 19 - TUGs | B25: QD2 | C25: Sistemas de Serra - Circuito 2 | D25: ='Divisão dos Circuitos'!K25 -> 8.1818182 | E25: 1 | F25: 1 | G25: 1 | H25: =D25/(E25*G25) -> 8.1818182 | I25: B2 | J25: PVC | K25: 2 | L25: 2.5
A26: 20 - TUGs | B26: QD2 | C26: Inspeção Final - Circuito 1 | D26: ='Divisão dos Circuitos'!K26 -> 8.1818182 | E26: 1 | F26: 1 | G26: 1 | H26: =D26/(E26*G26) -> 8.1818182 | I26: B2 | J26: PVC | K26: 2 | L26: 2.5
A27: 21 - TUGs | B27: QD2 | C27: Inspeção Final - Circuito 2 | D27: ='Divisão dos Circuitos'!K27 -> 8.1818182 | E27: 1 | F27: 1 | G27: 1 | H27: =D27/(E27*G27) -> 8.1818182 | I27: B2 | J27: PVC | K27: 2 | L27: 2.5
A28: 24 - TUGs Trifásicas | B28: QD2 | C28: Colagem e Montagem - Circuito 1 | D28: ='Divisão dos Circuitos'!K28 -> 18.232114 | E28: 1 | F28: 1 | G28: 1 | H28: =D28/(E28*G28) -> 18.232114 | I28: B2 | J28: PVC | K28: 3 | L28: 2.5
A29: 25 - TUGs Trifásicas | B29: QD2 | C29: Colagem e Montagem - Circuito 2 | D29: ='Divisão dos Circuitos'!K29 -> 18.232114 | E29: 1 | F29: 1 | G29: 1 | H29: =D29/(E29*G29) -> 18.232114 | I29: B2 | J29: PVC | K29: 3 | L29: 2.5
A30: 26 - TUGs Trifásicas | B30: QD2 | C30: Sistemas de Serra - Circuito 1 | D30: ='Divisão dos Circuitos'!K30 -> 18.232114 | E30: 1 | F30: 1 | G30: 1 | H30: =D30/(E30*G30) -> 18.232114 | I30: B2 | J30: PVC | K30: 3 | L30: 2.5
... A35: 49 - TUE Bancada 6 | B35: QD2 | C35: Bancada 6 | D35: ='Divisão dos Circuitos'!K35 -> 17.894737 | E35: 1 | F35: 1 | G35: 1 | H35: =D35/(E35*G35) -> 17.894737 | I35: B2 | J35: PVC | K35: 2 | L35: 2.5
A36: QD3 - QUADRO DE DISTRIBUIÇÃO 3
A37: 03 - Iluminação | B37: QD3 | C37: Sala de Estar, Reuniões, Recepção, Copa | D37: ='Divisão dos Circuitos'!K37 -> 8.9090909 | E37: 1 | F37: 3 | G37: 0.7 | H37: =D37/(E37*G37) -> 12.727273 | I37: B1 | J37: PVC | K37: 2 | L37: 1.5
A38: 06 - TUGs | B38: QD3 | C38: Copa | D38: ='Divisão dos Circuitos'!K38 -> 9.0909091 | E38: 1 | F38: 2 | G38: 0.8 | H38: =D38/(E38*G38) -> 11.363636 | I38: B1 | J38: PVC | K38: 2 | L38: 2.5
A39: 08 - TUGs | B39: QD3 | C39: Sanitários Administrativos (BWC 3 e 4) | D39: ='Divisão dos Circuitos'!K39 -> 5.4545455 | E39: 1 | F39: 3 | G39: 0.7 | H39: =D39/(E39*G39) -> 7.7922078 | I39: B1 | J39: PVC | K39: 2 | L39: 2.5
A40: 10 - TUGs | B40: QD3 | C40: Sala de Estar, Sala de Reuniões | D40: ='Divisão dos Circuitos'!K40 -> 13.181818 | E40: 1 | F40: 3 | G40: 0.7 | H40: =D40/(E40*G40) -> 18.831169 | I40: B1 | J40: PVC | K40: 2 | L40: 2.5
A41: 11 - TUGs | B41: QD3 | C41: Circulação 2 e 3 | D41: ='Divisão dos Circuitos'!K41 -> 6.3636364 | E41: 1 | F41: 3 | G41: 0.7 | H41: =D41/(E41*G41) -> 9.0909091 | I41: B1 | J41: PVC | K41: 2 | L41: 2.5
A42: 31 - TUE | B42: QD3 | C42: Secadores de Mãos - BWC 3 e 4 | D42: ='Divisão dos Circuitos'!K42 -> 13.914657 | E42: 1 | F42: 3 | G42: 0.7 | H42: =D42/(E42*G42) -> 19.878081 | I42: B1 | J42: PVC | K42: 2 | L42: 2.5
A43: 32 - TUE | B43: QD3 | C43: Ar Condicionado - Sala de Estar | D43: ='Divisão dos Circuitos'!K43 -> 9.3873518 | E43: 1 | F43: 3 | G43: 0.7 | H43: =D43/(E43*G43) -> 13.410503 | I43: B1 | J43: PVC | K43: 2 | L43: 2.5
A44: 33 - TUE | B44: QD3 | C44: Ar Condicionado - Sala de Reuniões | D44: ='Divisão dos Circuitos'!K44 -> 12.351779 | E44: 1 | F44: 3 | G44: 0.7 | H44: =D44/(E44*G44) -> 17.645398 | I44: B1 | J44: PVC | K44: 2 | L44: 2.5
A45: 34 - TUE | B45: QD3 | C45: Ar Condicionado - Recepção | D45: ='Divisão dos Circuitos'!K45 -> 6.916996 | E45: 1 | F45: 3 | G45: 0.7 | H45: =D45/(E45*G45) -> 9.8814229 | I45: B1 | J45: PVC | K45: 2 | L45: 2.5
...

Sheet Queda de Tensão
A1: CRITÉRIO DE QUEDA DE TENSÃO
A3: Circuito N° - Tipo | B3: Origem | C3: Destino | D3: IN [A] | E3: VN [V] | F3: k | G3: ρ [Ω.mm²/m] | H3: L [m] | I3: Queda de tensão (Máx) [%] | J3: Seção Calculada [mm²] | K3: S3 - Seção Comercial [mm²]
A4: QD1 - QUADRO DE DISTRIBUIÇÃO 1
A5: 01 - Iluminação | B5: QD1 | C5: Tornear e Chanfrar, Polimento | D5: ='Divisão dos Circuitos'!K5 -> 10.84022 | E5: 220 | F5: 2 | G5: 0.0178 | H5: 56.1 | I5: 2.5 | J5: =(F5*G5*H5*D5*100)/(I5*E5) -> 3.9363008 | K5: =IF(J5<=1.5, 1.5, IF(J5<=2.5, 2.5, IF(J5<=4, 4, IF(J5<=6, 6, IF(J5<=10, 10, 16))))) -> 4
A6: 12 - TUGs | B6: QD1 | C6: Tornear e Chanfrar - Circuito 1 | D6: ='Divisão dos Circuitos'!K6 -> 10.909091 | E6: 220 | F6: 2 | G6: 0.0178 | H6: 27.8 | I6: 2.5 | J6: =(F6*G6*H6*D6*100)/(I6*E6) -> 1.9630017 | K6: =IF(J6<=1.5, 1.5, IF(J6<=2.5, 2.5, IF(J6<=4, 4, IF(J6<=6, 6, IF(J6<=10, 10, 16))))) -> 2.5
A7: 13 - TUGs | B7: QD1 | C7: Tornear e Chanfrar - Circuito 2 | D7: ='Divisão dos Circuitos'!K7 -> 8.1818182 | E7: 220 | F7: 2 | G7: 0.0178 | H7: 15.4 | I7: 2.5 | J7: =(F7*G7*H7*D7*100)/(I7*E7) -> 0.81556364 | K7: =IF(J7<=1.5, 1.5, IF(J7<=2.5, 2.5, IF(J7<=4, 4, IF(J7<=6, 6, IF(J7<=10, 10, 16))))) -> 1.5
A8: 14 - TUGs | B8: QD1 | C8: Polimento - Circuito 1 | D8: ='Divisão dos Circuitos'!K8 -> 10.909091 | E8: 220 | F8: 2 | G8: 0.0178 | H8: 44.5 | I8: 2.5 | J8: =(F8*G8*H8*D8*100)/(I8*E8) -> 3.1422149 | K8: =IF(J8<=1.5, 1.5, IF(J8<=2.5, 2.5, IF(J8<=4, 4, IF(J8<=6, 6, IF(J8<=10, 10, 16))))) -> 4
A9: 15 - TUGs | B9: QD1 | C9: Polimento - Circuito 2 | D9: ='Divisão dos Circuitos'!K9 -> 8.1818182 | E9: 220 | F9: 2 | G9: 0.0178 | H9: 54 | I9: 2.5 | J9: =(F9*G9*H9*D9*100)/(I9*E9) -> 2.8597686 | K9: =IF(J9<=1.5, 1.5, IF(J9<=2.5, 2.5, IF(J9<=4, 4, IF(J9<=6, 6, IF(J9<=10, 10, 16))))) -> 4
A10: 22 - TUGs Trifásicas | B10: QD1 | C10: Tornear e Chanfrar - Circuito 1 | D10: ='Divisão dos Circuitos'!K10 -> 18.232114 | E10: 380 | F10: 1.732 | G10: 0.0178 | H10: 25.7 | I10: 2.5 | J10: =(F10*G10*H10*D10*100)/(I10*E10) -> 1.5205981 | K10: =IF(J10<=1.5, 1.5, IF(J10<=2.5, 2.5, IF(J10<=4, 4, IF(J10<=6, 6, IF(J10<=10, 10, 16))))) -> 2.5
A11: 23 - TUGs Trifásicas | B11: QD1 | C11: Polimento - Circuito 1 | D11: ='Divisão dos Circuitos'!K11 -> 18.232114 | E11: 380 | F11: 1.732 | G11: 0.0178 | H11: 42.2 | I11: 2.5 | J11: =(F11*G11*H11*D11*100)/(I11*E11) -> 2.4968575 | K11: =IF(J11<=1.5, 1.5, IF(J11<=2.5, 2.5, IF(J11<=4, 4, IF(J11<=6, 6, IF(J11<=10, 10, 16))))) -> 2.5
A12: 38 - TUGs Trifásicas | B12: QD1 | C12: Tornear e Chanfrar - Circuito 2 | D12: ='Divisão dos Circuitos'!K12 -> 18.232114 | E12: 380 | F12: 1.732 | G12: 0.0178 | H12: 15 | I12: 2.5 | J12: =(F12*G12*H12*D12*100)/(I12*E12) -> 0.88750859 | K12: =IF(J12<=1.5, 1.5, IF(J12<=2.5, 2.5, IF(J12<=4, 4, IF(J12<=6, 6, IF(J12<=10, 10, 16))))) -> 1.5
A13: 39 - TUGs Trifásicas | B13: QD1 | C13: Polimento - Circuito 2 | D13: ='Divisão dos Circuitos'!K13 -> 18.232114 | E13: 380 | F13: 1.732 | G13: 0.0178 | H13: 52.5 | I13: 2.5 | J13: =(F13*G13*H13*D13*100)/(I13*E13) -> 3.1062801 | K13: =IF(J13<=1.5, 1.5, IF(J13<=2.5, 2.5, IF(J13<=4, 4, IF(J13<=6, 6, IF(J13<=10, 10, 16))))) -> 4
A14: 44 - TUE Bancada 1 | B14: QD1 | C14: Bancada 1 | D14: ='Divisão dos Circuitos'!K14 -> 13.636364 | E14: 220 | F14: 2 | G14: 0.0178 | H14: 27.7 | I14: 2.5 | J14: =(F14*G14*H14*D14*100)/(I14*E14) -> 2.4449256 | K14: =IF(J14<=1.5, 1.5, IF(J14<=2.5, 2.5, IF(J14<=4, 4, IF(J14<=6, 6, IF(J14<=10, 10, 16))))) -> 2.5
A15: 45 - TUE Bancada 2 | B15: QD1 | C15: Bancada 2 | D15: ='Divisão dos Circuitos'!K15 -> 10 | E15: 220 | F15: 2 | G15: 0.0178 | H15: 30.1 | I15: 2.5 | J15: =(F15*G15*H15*D15*100)/(I15*E15) -> 1.9482909 | K15: =IF(J15<=1.5, 1.5, IF(J15<=2.5, 2.5, IF(J15<=4, 4, IF(J15<=6, 6, IF(J15<=10, 10, 16))))) -> 2.5
A16: 46 - TUE Bancada 3 | B16: QD1 | C16: Bancada 3 | D16: ='Divisão dos Circuitos'!K16 -> 9.0909091 | E16: 220 | F16: 2 | G16: 0.0178 | H16: 34 | I16: 2.5 | J16: =(F16*G16*H16*D16*100)/(I16*E16) -> 2.0006612 | K16: =IF(J16<=1.5, 1.5, IF(J16<=2.5, 2.5, IF(J16<=4, 4, IF(J16<=6, 6, IF(J16<=10, 10, 16))))) -> 2.5
A17: 47 - TUE Bancada 4 | B17: QD1 | C17: Bancada 4 | D17: ='Divisão dos Circuitos'!K17 -> 15.454545 | E17: 220 | F17: 2 | G17: 0.0178 | H17: 35 | I17: 2.5 | J17: =(F17*G17*H17*D17*100)/(I17*E17) -> 3.501157 | K17: =IF(J17<=1.5, 1.5, IF(J17<=2.5, 2.5, IF(J17<=4, 4, IF(J17<=6, 6, IF(J17<=10, 10, 16))))) -> 4
A18: QD2 - QUADRO DE DISTRIBUIÇÃO 2
A19: 02 - Iluminação | B19: QD2 | C19: Colagem e Montagem, Sistemas de Serra, BWC 1 e 2 | D19: ='Divisão dos Circuitos'!K19 -> 8.87236 | E19: 220 | F19: 2 | G19: 0.0178 | H19: 45.1 | I19: 2.5 | J19: =(F19*G19*H19*D19*100)/(I19*E19) -> 2.5900193 | K19: =IF(J19<=1.5, 1.5, IF(J19<=2.5, 2.5, IF(J19<=4, 4, IF(J19<=6, 6, IF(J19<=10, 10, 16))))) -> 4
A20: 05 - Iluminação | B20: QD2 | C20: Inspeção Final | D20: ='Divisão dos Circuitos'!K20 -> 7.5881543 | E20: 220 | F20: 2 | G20: 0.0178 | H20: 42.9 | I20: 2.5 | J20: =(F20*G20*H20*D20*100)/(I20*E20) -> 2.1070787 | K20: =IF(J20<=1.5, 1.5, IF(J20<=2.5, 2.5, IF(J20<=4, 4, IF(J20<=6, 6, IF(J20<=10, 10, 16))))) -> 2.5
A21: 07 - TUGs | B21: QD2 | C21: Sanitários Operacionais (BWC 1 e 2) | D21: ='Divisão dos Circuitos'!K21 -> 5.4545455 | E21: 220 | F21: 2 | G21: 0.0178 | H21: 17.7 | I21: 2.5 | J21: =(F21*G21*H21*D21*100)/(I21*E21) -> 0.6249124 | K21: =IF(J21<=1.5, 1.5, IF(J21<=2.5, 2.5, IF(J21<=4, 4, IF(J21<=6, 6, IF(J21<=10, 10, 16))))) -> 1.5
A22: 16 - TUGs | B22: QD2 | C22: Colagem e Montagem - Circuito 1 | D22: ='Divisão dos Circuitos'!K22 -> 10.909091 | E22: 220 | F22: 2 | G22: 0.0178 | H22: 25.8 | I22: 2.5 | J22: =(F22*G22*H22*D22*100)/(I22*E22) -> 1.8217785 | K22: =IF(J22<=1.5, 1.5, IF(J22<=2.5, 2.5, IF(J22<=4, 4, IF(J22<=6, 6, IF(J22<=10, 10, 16))))) -> 2.5
A23: 17 - TUGs | B23: QD2 | C23: Colagem e Montagem - Circuito 2 | D23: ='Divisão dos Circuitos'!K23 -> 8.1818182 | E23: 220 | F23: 2 | G23: 0.0178 | H23: 18.5 | I23: 2.5 | J23: =(F23*G23*H23*D23*100)/(I23*E23) -> 0.97973554 | K23: =IF(J23<=1.5, 1.5, IF(J23<=2.5, 2.5, IF(J23<=4, 4, IF(J23<=6, 6, IF(J23<=10, 10, 16))))) -> 1.5
A24: 18 - TUGs | B24: QD2 | C24: Sistemas de Serra - Circuito 1 | D24: ='Divisão dos Circuitos'!K24 -> 10.909091 | E24: 220 | F24: 2 | G24: 0.0178 | H24: 42.7 | I24: 2.5 | J24: =(F24*G24*H24*D24*100)/(I24*E24) -> 3.015114 | K24: =IF(J24<=1.5, 1.5, IF(J24<=2.5, 2.5, IF(J24<=4, 4, IF(J24<=6, 6, IF(J24<=10, 10, 16))))) -> 4
A25: 19 - TUGs | B25: QD2 | C25: Sistemas de Serra - Circuito 2 | D25: ='Divisão dos Circuitos'!K25 -> 8.1818182 | E25: 220 | F25: 2 | G25: 0.0178 | H25: 39.5 | I25: 2.5 | J25: =(F25*G25*H25*D25*100)/(I25*E25) -> 2.0918678 | K25: =IF(J25<=1.5, 1.5, IF(J25<=2.5, 2.5, IF(J25<=4, 4, IF(J25<=6, 6, IF(J25<=10, 10, 16))))) -> 2.5
A26: 20 - TUGs | B26: QD2 | C26: Inspeção Final - Circuito 1 | D26: ='Divisão dos Circuitos'!K26 -> 8.1818182 | E26: 220 | F26: 2 | G26: 0.0178 | H26: 30.4 | I26: 2.5 | J26: =(F26*G26*H26*D26*100)/(I26*E26) -> 1.6099438 | K26: =IF(J26<=1.5, 1.5, IF(J26<=2.5, 2.5, IF(J26<=4, 4, IF(J26<=6, 6, IF(J26<=10, 10, 16))))) -> 2.5
A27: 21 - TUGs | B27: QD2 | C27: Inspeção Final - Circuito 2 | D27: ='Divisão dos Circuitos'!K27 -> 8.1818182 | E27: 220 | F27: 2 | G27: 0.0178 | H27: 34.4 | I27: 2.5 | J27: =(F27*G27*H27*D27*100)/(I27*E27) -> 1.8217785 | K27: =IF(J27<=1.5, 1.5, IF(J27<=2.5, 2.5, IF(J27<=4, 4, IF(J27<=6, 6, IF(J27<=10, 10, 16))))) -> 2.5
A28: 24 - TUGs Trifásicas | B28: QD2 | C28: Colagem e Montagem - Circuito 1 | D28: ='Divisão dos Circuitos'!K28 -> 18.232114 | E28: 380 | F28: 1.732 | G28: 0.0178 | H28: 23.9 | I28: 2.5 | J28: =(F28*G28*H28*D28*100)/(I28*E28) -> 1.414097 | K28: =IF(J28<=1.5, 1.5, IF(J28<=2.5, 2.5, IF(J28<=4, 4, IF(J28<=6, 6, IF(J28<=10, 10, 16))))) -> 1.5
A29: 25 - TUGs Trifásicas | B29: QD2 | C29: Colagem e Montagem - Circuito 2 | D29: ='Divisão dos Circuitos'!K29 -> 18.232114 | E29: 380 | F29: 1.732 | G29: 0.0178 | H29: 16.6 | I29: 2.5 | J29: =(F29*G29*H29*D29*100)/(I29*E29) -> 0.98217617 | K29: =IF(J29<=1.5, 1.5, IF(J29<=2.5, 2.5, IF(J29<=4, 4, IF(J29<=6, 6, IF(J29<=10, 10, 16))))) -> 1.5
